Workbook

Sheet Final Work
A1: GREEN MARINE CO., LTD.
B2: FINAL WORKING REPORT (VOUCHER)
A4: M/V : | B4: SAWASDEE RIGEL | F4: VOY # : | K4: DATE :
A6: PIER : | F6: BERTH : | K6: PORT : | L6: PYEONGTAEK, KOREA
A8: OPERATOR | B8: PORT | C8: FULL / EMPTY | D8: =+"DISCH ("&D70+E70+F70+G70+D71+E71+F71+G71&")" -> DISCH (340) | H8: =+"LOAD ("&H70+I70+J70+K70+H71+I71+J71+K71&")" -> LOAD (375) | L8: =+"SHIFT ("&L70+M70+N70+O70+L71+M71+N71+O71&")" -> SHIFT (0)
D9: 20' | E9: 40' | F9: HC | G9: 45' | H9: 20' | I9: 40' | J9: HC | K9: 45' | L9: 20' | M9: 40' | N9: HC | O9: 45'
C10: F
C11: E
C12: F
C13: E
C14: F
C15: E
C16: F
C17: E
C18: F
C19: E
C20: F
C21: E
... C69: E
A70: Total | D70: =SUM(D10,D12,D14,D16,D18,D20,D22,D24,D26,D28,D30,D32,D34,D36,D38,D40,D42,D44,D46,D48,D50,D52,D54,D56,D58,D60,D62,D64,D66,D68) -> 105 | E70: =SUM(E10,E12,E14,E16,E18,E20,E22,E24,E26,E28,E30,E32,E34,E36,E38,E40,E42,E44,E46,E48,E50,E52,E54,E56,E58,E60,E62,E64,E66,E68) -> 0 | F70: =SUM(F10,F12,F14,F16,F18,F20,F22,F24,F26,F28,F30,F32,F34,F36,F38,F40,F42,F44,F46,F48,F50,F52,F54,F56,F58,F60,F62,F64,F66,F68) -> 235 | G70: =SUM(G10,G12,G14,G16,G18,G20,G22,G24,G26,G28,G30,G32,G34,G36,G38,G40,G42,G44,G46,G48,G50,G52,G54,G56,G58,G60,G62,G64,G66,G68) -> 0 | H70: =SUM(H10,H12,H14,H16,H18,H20,H22,H24,H26,H28,H30,H32,H34,H36,H38,H40,H42,H44,H46,H48,H50,H52,H54,H56,H58,H60,H62,H64,H66,H68) -> 0 | I70: =SUM(I10,I12,I14,I16,I18,I20,I22,I24,I26,I28,I30,I32,I34,I36,I38,I40,I42,I44,I46,I48,I50,I52,I54,I56,I58,I60,I62,I64,I66,I68) -> 0 | J70: =SUM(J10,J12,J14,J16,J18,J20,J22,J24,J26,J28,J30,J32,J34,J36,J38,J40,J42,J44,J46,J48,J50,J52,J54,J56,J58,J60,J62,J64,J66,J68) -> 0 | K70: =SUM(K10,K12,K14,K16,K18,K20,K22,K24,K26,K28,K30,K32,K34,K36,K38,K40,K42,K44,K46,K48,K50,K52,K54,K56,K58,K60,K62,K64,K66,K68) -> 0 | ... O70: =SUM(O10,O12,O14,O16,O18,O20,O22,O24,O26,O28,O30,O32,O34,O36,O38,O40,O42,O44,O46,O48,O50,O52,O54,O56,O58,O60,O62,O64,O66,O68) -> 0
D71: =SUM(D11,D13,D15,D17,D19,D21,D23,D25,D27,D29,D31,D33,D35,D37,D39,D41,D43,D45,D47,D49,D51,D53,D55,D57,D59,D61,D63,D65,D67,D69) -> 0 | E71: =SUM(E11,E13,E15,E17,E19,E21,E23,E25,E27,E29,E31,E33,E35,E37,E39,E41,E43,E45,E47,E49,E51,E53,E55,E57,E59,E61,E63,E65,E67,E69) -> 0 | F71: =SUM(F11,F13,F15,F17,F19,F21,F23,F25,F27,F29,F31,F33,F35,F37,F39,F41,F43,F45,F47,F49,F51,F53,F55,F57,F59,F61,F63,F65,F67,F69) -> 0 | G71: =SUM(G11,G13,G15,G17,G19,G21,G23,G25,G27,G29,G31,G33,G35,G37,G39,G41,G43,G45,G47,G49,G51,G53,G55,G57,G59,G61,G63,G65,G67,G69) -> 0 | H71: =SUM(H11,H13,H15,H17,H19,H21,H23,H25,H27,H29,H31,H33,H35,H37,H39,H41,H43,H45,H47,H49,H51,H53,H55,H57,H59,H61,H63,H65,H67,H69) -> 8 | I71: =SUM(I11,I13,I15,I17,I19,I21,I23,I25,I27,I29,I31,I33,I35,I37,I39,I41,I43,I45,I47,I49,I51,I53,I55,I57,I59,I61,I63,I65,I67,I69) -> 0 | J71: =SUM(J11,J13,J15,J17,J19,J21,J23,J25,J27,J29,J31,J33,J35,J37,J39,J41,J43,J45,J47,J49,J51,J53,J55,J57,J59,J61,J63,J65,J67,J69) -> 367 | K71: =SUM(K11,K13,K15,K17,K19,K21,K23,K25,K27,K29,K31,K33,K35,K37,K39,K41,K43,K45,K47,K49,K51,K53,K55,K57,K59,K61,K63,K65,K67,K69) -> 0 | ... O71: =SUM(O11,O13,O15,O17,O19,O21,O23,O25,O27,O29,O31,O33,O35,O37,O39,O41,O43,O45,O47,O49,O51,O53,O55,O57,O59,O61,O63,O65,O67,O69) -> 0
A73: Remarks : Discharging | H73: Remarks : Loading
A83: CHIEF CHECKER | J83: CHIEF OFFICER

Sheet Time Sheet
A1: GREEN MARINE CO., LTD.
A2: PYEONGTAEK, KOREA
C3: T I M E S H E E T
A6: M / V : | C6: VOY # : | G6: DATE : | H6: ='Final Work'!L4 -> 46214
A8: PIER : | C8: BERTH : | G8: WEATHER :
H10: PORT : PYEONGTAEK, KOREA
A12: T I M E | C12: R E M A R K S
A46: CHIEF CHECKER

Sheet OS-IN
A1: GREEN MARINE CO., LTD.
A2: PYEONGTAEK, KOREA
A4: CARGO OVERAGE & SHORTAGE REPORT (DISCH)
A6: M / V : | B6: ='Final Work'!B4 -> SAWASDEE RIGEL | G6: VOY. NO.: | K6: DATE :
A8: PORT : | B8: PYEONGTAEK, KOREA | G8: PIER : | K8: BERTH :
A10: B/L NO. | B10: MARKS (PORT) | D10: DESCRIPTION | G10: TYPE OF | H10: MANIFESTED | J10: DISCHARGED | K10: OVER | L10: SHORT | M10: REMARKS
G11: PKGS
D23: T O T A L | G23: VAN | H23: =SUM(H9:I22) -> 340 | J23: =SUM(J9:J22) -> 340 | K23: NIL | L23: NIL
A35: CHIEF CHECKER | G35: STEVEDORE PCTC | L35: CHIEF OFFICER

Sheet DM-IN
A1: GREEN MARINE CO., LTD.
A2: PYEONGTAEK, KOREA
A4: CARGO DAMAGE REPORT
A6: M / V : | B6: ='Final Work'!B4 -> SAWASDEE RIGEL | H6: VOY. NO. : | J6: ='OS-IN'!H6 -> 2606N | O6: DATE : | P6: ='OS-IN'!L6 -> 46214
A8: PORT : | B8: PYEONGTAEK, KOREA | H8: PIER : | J8: PCTC | O8: BERTH : | P8: ='OS-IN'!L8 -> 6
A10: PORT | B10: B/L NO. | C10: MARKS | F10: CONTENTS | J10: NO. OF | K10: TYPE | L10: EXCEPTION ( Found In Stow )
J11: PKGS
A12: SGN | B12: HAS | C12: HLHU8469768 | F12: 40' FULL CONT'R | J12: 1 | K12: VAN | L12: R/SIDE PANEL 1 POINT DENTED (100cm x 50cm)
A13: SGN | B13: SKR | C13: HLHU8455825 | F13: 40' FULL CONT'R | J13: 1 | K13: VAN | L13: L/SIDE PANEL 1 POINT DENTED (50cm x 50cm)
A33: CHIEF CHECKER | I33: STEVEDORE PCTC | O33: CHIEF OFFICER

Sheet OS-OUT
A1: GREEN MARINE CO., LTD.
A2: PYEONGTAEK, KOREA
A4: CARGO OVERAGE & SHORTAGE REPORT (LOAD)
A6: M / V : | B6: ='Final Work'!B4 -> SAWASDEE RIGEL | G6: VOY. NO.: | K6: DATE :
A8: PORT : | B8: PYEONGTAEK, KOREA | G8: PIER : | K8: BERTH :
A10: B/L NO. | B10: MARKS (PORT) | D10: DESCRIPTION | G10: TYPE OF | H10: MANIFESTED | J10: LOADED | K10: OVER | L10: SHORT | M10: REMARKS
G11: PKGS
D28: T O T A L | G28: VAN | H28: =SUM(H14:I18) -> 375 | J28: =SUM(J14:J18) -> 375 | K28: NIL | L28: NIL
A39: CHIEF CHECKER | G39: STEVEDORE PCTC | L39: CHIEF OFFICER

Sheet DM-OUT
A1: GREEN MARINE CO., LTD.
A2: PYEONGTAEK, KOREA
A4: CARGO DAMAGE REPORT
A6: M / V : | B6: ='Final Work'!B4 -> SAWASDEE RIGEL | H6: VOY. NO. : | J6: ='OS-OUT'!H6 -> 2606N | O6: DATE : | P6: ='OS-OUT'!L6 -> 46214
A8: PORT : | B8: PYEONGTAEK, KOREA | H8: PIER : | J8: PCTC | O8: BERTH : | P8: ='Final Work'!G6 -> 6
A10: PORT | B10: B/L NO. | C10: MARKS | F10: CONTENTS | J10: NO. OF | K10: TYPE | L10: EXCEPTION ( Prior To Load )
J11: PKGS
A12: PTK
A33: CHIEF CHECKER | I33: STEVEDORE PCTC | O33: CHIEF OFFICER

Sheet Act. Cntr-Seal No List
A1: GREEN MARINE CO., LTD.
A2: PYEONGTAEK, KOREA
A4: M / V : | B4: ='Final Work'!B4 -> SAWASDEE RIGEL | F4: DATE :
A6: VOY # : | B6: ='OS-IN'!H6 -> 2606N | F6: PORT : | G6: PYEONGTAEK, KOREA
B8: ACTUAL CONTAINER & SEAL NUMBER LIST
H9: DISCH.
A10: MANIFEST | D10: SIZE | E10: ACTUAL | G10: RESEAL NO. | H10: REMARKS
A11: CONT'R NO. | C11: SEAL NO. | E11: CONT'R NO. | F11: SEAL NO.
A33: 20FT | B33: FULL
B34: EMPTY
A35: 40FT | B35: FULL | C35: 2
B36: EMPTY
A37: TOTAL | C37: =SUM(C33:C36) -> 2 | G37: CHIEF CHECKER
A38: GREEN MARINE CO., LTD.
A39: PYEONGTAEK, KOREA
A41: M / V : | B41: ='Final Work'!B4 -> SAWASDEE RIGEL | F41: DATE : | G41: ='OS-OUT'!L6 -> 46214
A43: VOY # : | B43: ='OS-OUT'!H6 -> 2606N | F43: PORT : | G43: PYEONGTAEK, KOREA
B45: ACTUAL CONTAINER & SEAL NUMBER LIST
H46: LOAD.
A47: MANIFEST | D47: SIZE | E47: ACTUAL | G47: RESEAL NO. | H47: REMARKS
A48: CONT'R NO. | C48: SEAL NO. | E48: CONT'R NO. | F48: SEAL NO.
A49: NIL
A70: 20FT | B70: FULL
B71: EMPTY
A72: 40FT | B72: FULL
B73: EMPTY
A74: TOTAL | C74: =SUM(C70:C73) -> 0 | G74: CHIEF CHECKER

Sheet RF Condition Report
A1: GREEN MARINE CO., LTD.
A2: PYEONGTAEK, KOREA
A4: REEFER CONTAINER CONDITION REPORT
A5: Discharging / Loading
I6: ( 1/2 )
A7: M / V : SAWASDEE RIGEL | D7: VOY # : | E7: ='OS-IN'!H6 -> 2606N | G7: DATE : | H7: ='OS-IN'!L6 -> 46214
A8: PIER : PCTC | D8: BERTH : | E8: ='Final Work'!G6 -> 6 | G8: PORT : | H8: PYEONGTAEK, KOREA
A10: CONTAINER NO. | B10: SEAL NO. | C10: SIZE | D10: LOCATION | F10: TEMPERATURE | H10: TIME | I10: REMARKS
D11: Bay/Slot/Tier | F11: Setting | G11: Actual | H11: Plug In / Out
A44: CHIEF CHECKER | D44: STEVEDORE PCTC | H44: CHIEF OFFICER
A45: GREEN MARINE CO., LTD.
A46: PYEONGTAEK, KOREA
A48: REEFER CONTAINER CONDITION REPORT
A49: Discharging / Loading
I50: ( 2/2 )
A51: =A7 -> M / V : SAWASDEE RIGEL | D51: VOY # : | E51: ='OS-IN'!H6 -> 2606N | G51: DATE : | H51: ='OS-IN'!L6 -> 46214
A52: PIER : PCTC | D52: BERTH : | E52: ='Final Work'!G6 -> 6 | G52: PORT : | H52: PYEONGTAEK, KOREA
A54: CONTAINER NO. | B54: SEAL NO. | C54: SIZE | D54: LOCATION | F54: TEMPERATURE | H54: TIME | I54: REMARKS
D55: Bay/Slot/Tier | F55: Setting | G55: Actual | H55: Plug In / Out
A56: FSCU5911610 | C56: 40'RH | F56: -18.0C | G56: -18.1 | H56: =H12 -> NaN | I56: BKK - HAS
A57: HALU8500359 | C57: 40'RH | F57: 14.0C | G57: 14.0C | H57: " | I57: SGN - HAS
A58: HALU8503260 | C58: 40'RH | F58: 13.5C | G58: 13.3 | H58: " | I58: SGN - SKR
A59: HALU8505047 | C59: 40'RH | F59: -18.0C | G59: -17.8 | H59: " | I59: BKK - HAS
A60: HALU8505073 | C60: 40'RH | F60: -18.0C | G60: -18.0C | H60: " | I60: LCH - SKR
A61: SKRU6504717 | C61: 40'RH | F61: 14.0C | G61: 14.0C | H61: " | I61: SGN - SKR
A62: SKRU6507296 | C62: 40'RH | F62: 14.0C | G62: 13.9 | H62: " | I62: SGN - HAS
A63: SKRU9602851 | C63: 40'RH | F63: 3.0C | G63: 3.0C | H63: " | I63: SGN - HAS
A64: SZLU9371622 | C64: 40'RH | F64: 14.0C | G64: 14.1 | H64: " | I64: SGN - HAS
A65: SZLU9372167 | C65: 40'RH | F65: -20.0C | G65: -20.0C | H65: " | I65: SGN - HAS
A66: SZLU9373353 | C66: 40'RH | F66: 14.0C | G66: 14.1 | H66: " | I66: SGN - SKR
A77: < CY 보관지침 >
A78: 1. 최초 화주로 부터 지정된 온도(SETTING 온도를 말하며 수입목록 혹은 BAY PLAN에
A79: 표기된 온도)는 그 적정 온도를 유지하고 있는지 4시간마다 확인하여 기록 보관해야한다.
A80: 2. 온도를 지정하는 지시 및 표기가 없을 경우 일반적으로 채용되고 있는
A81: 냉동/냉장 화물의 운송온도를 기준으로 한다.
A82: 3. 만일 온도 이상 및 기타 기기의 이상이 발견될 시는 즉시 OPERATOR에게 통보하여야한다.
A88: CHIEF CHECKER | D88: STEVEDORE PCTC | H88: CHIEF OFFICER
A89: GREEN MARINE CO., LTD.
A90: PYEONGTAEK, KOREA
A92: REEFER CONTAINER CONDITION REPORT
...

Sheet Performance
A1: GREEN MARINE CO., LTD
A2: PYEONGTAEK, KOREA
A4: PERFORMANCE REPORT
A6: M / V : | D6: ='Final Work'!B4 -> SAWASDEE RIGEL | O6: VOY # : | R6: ='Final Work'!G4 -> 2606N & 2606N | Y6: DATE : | AB6: ='Final Work'!L4 -> 46214
A8: PIER : | D8: PCTC | O8: BERTH : | R8: ='Final Work'!G6 -> 6 | Y8: PORT : | AB8: PYEONGTAEK, KOREA
A10: Status | H10: FULL | P10: EMPTY | X10: TOTAL | AA10: REMARKS
A11: Description | H11: 20' | J11: 40' | L11: HC | N11: 45' | P11: 20' | R11: 40' | T11: HC | V11: 45'
A12: IN BOUND | X12: =SUM(H12:W12) -> 203 | AA12: 20'RF x 2 , RH x 12
X13: =SUM(H13:W13) -> 130 | AA13: 20'RF X 1 , 20'OT x 1, RH x 16
X14: =SUM(H14:W14) -> 7
X15: =SUM(H15:W15) -> 0
X16: =SUM(H16:W16) -> 0
X17: =SUM(H17:W17) -> 0
X18: =SUM(H18:W18) -> 0
D19: S-TOTAL | H19: =SUM(H12:I18) -> 105 | J19: =SUM(J12:K18) -> 0 | L19: =SUM(L12:M18) -> 235 | N19: =SUM(N12:O18) -> 0 | P19: =SUM(P12:Q18) -> 0 | R19: =SUM(R12:S18) -> 0 | T19: =SUM(T12:U18) -> 0 | V19: =SUM(V12:W18) -> 0 | X19: =SUM(X12:Z18) -> 340
A20: OUT BOUND | X20: =SUM(H20:W20) -> 0
X21: =SUM(H21:W21) -> 375
X22: =SUM(H22:W22) -> 0
X23: =SUM(H23:W23) -> 0
X24: =SUM(H24:W24) -> 0
X25: =SUM(H25:W25) -> 0
X26: =SUM(H26:W26) -> 0
D27: S-TOTAL | H27: =SUM(H20:I26) -> 0 | J27: =SUM(J20:K26) -> 0 | L27: =SUM(L20:M26) -> 0 | N27: =SUM(N20:O26) -> 0 | P27: =SUM(P20:Q26) -> 8 | R27: =SUM(R20:S26) -> 0 | T27: =SUM(T20:U26) -> 367 | V27: =SUM(V20:W26) -> 0 | X27: =SUM(X20:Z26) -> 375
A28: SHIFT | D28: 1 TIME
D29: 1 TIME
A30: GRAND TOTAL | H30: =SUM(H19+H27+H28+H29) -> 105 | J30: =SUM(J19+J27+J28+J29) -> 0 | L30: =SUM(L19+L27+L28+L29) -> 235 | N30: =SUM(N19+N27+N28+N29) -> 0 | P30: =SUM(P19+P27+P28+P29) -> 8 | R30: =SUM(R19+R27+R28+R29) -> 0 | T30: =SUM(T19+T27+T28+T29) -> 367 | V30: =SUM(V19+V27+V28+V29) -> 0 | X30: =SUM(X19+X27+X28+X29) -> 715
A32: # WORKING PERIOD
A34: CRANE NO. | E34: FROM | K34: TO | Q34: HOURS | W34: REMARKS
A35: #1 (G/C) | Q35: =IF(AND(NOT(ISBLANK(K35)),NOT(ISBLANK(E35))), IF(K35>E35,K35-E35,24-E35+K35), "") | W35: COMMENCED DISCH.
Q36: =IF(AND(NOT(ISBLANK(K36)),NOT(ISBLANK(E36))), IF(K36>E36,K36-E36,24-E36+K36), "") | W36: DISCH. OF CONT'R
Q37: =IF(AND(NOT(ISBLANK(K37)),NOT(ISBLANK(E37))), IF(K37>E37,K37-E37,24-E37+K37), "") | W37: MEAL TIME
Q38: =IF(AND(NOT(ISBLANK(K38)),NOT(ISBLANK(E38))), IF(K38>E38,K38-E38,24-E38+K38), "") | W38: DISCH. OF CONT'R
Q39: =IF(AND(NOT(ISBLANK(K39)),NOT(ISBLANK(E39))), IF(K39>E39,K39-E39,24-E39+K39), "") | W39: MEAL TIME
Q40: =IF(AND(NOT(ISBLANK(K40)),NOT(ISBLANK(E40))), IF(K40>E40,K40-E40,24-E40+K40), "") | W40: DISCH. OF CONT'R
Q41: =IF(AND(NOT(ISBLANK(K41)),NOT(ISBLANK(E41))), IF(K41>E41,K41-E41,24-E41+K41), "") | W41: COMPLETED DISCH
Q42: =IF(AND(NOT(ISBLANK(K42)),NOT(ISBLANK(E42))), IF(K42>E42,K42-E42,24-E42+K42), "") | W42: COMMENCED LOAD.
Q43: =IF(AND(NOT(ISBLANK(K43)),NOT(ISBLANK(E43))), IF(K43>E43,K43-E43,24-E43+K43), "") | W43: LOAD. OF CONT'R
Q44: =IF(AND(NOT(ISBLANK(K44)),NOT(ISBLANK(E44))), IF(K44>E44,K44-E44,24-E44+K44), "") | W44: MEAL TIME
Q45: =IF(AND(NOT(ISBLANK(K45)),NOT(ISBLANK(E45))), IF(K45>E45,K45-E45,24-E45+K45), "") | W45: LOAD. OF CONT'R
Q46: =IF(AND(NOT(ISBLANK(K46)),NOT(ISBLANK(E46))), IF(K46>E46,K46-E46,24-E46+K46), "") | W46: TEA TIME
...
