Workbook
Name 모선이름: 'Time Sheet'!$B$6
Name 선적종료일: 'Time Sheet'!$H$6
Name 선적항차: 'RF Condition Report'!$E$55
Name 양하종료일: 'RF Condition Report'!$H$7
Name 작업선석: 'Time Sheet'!$D$8
Name 작업항차: 'Time Sheet'!$D$6

Sheet Final Work
A1: GREEN MARINE CO., LTD.
B2: FINAL WORKING REPORT (VOUCHER)
A4: M/V : | B4: YOKOHAMA TRADER | F4: VOY # : | K4: DATE :
A6: PIER : | F6: BERTH : | K6: PORT : | L6: PYEONGTAEK, KOREA
A8: OPERATOR | B8: PORT | C8: FULL / EMPTY | D8: =+"DISCH ("&D72+E72+F72+G72+D73+E73+F73+G73&")" -> DISCH (196) | H8: =+"LOAD ("&H72+I72+J72+K72+H73+I73+J73+K73&")" -> LOAD (160) | L8: =+"SHIFT ("&L72+M72+N72+O72+L73+M73+N73+O73&")" -> SHIFT (0)
D9: 20' | E9: 40' | F9: HC | G9: 45' | H9: 20' | I9: 40' | J9: HC | K9: 45' | L9: 20' | M9: 40' | N9: HC | O9: 45'
C10: F
C11: E
C12: F
C13: E
C14: F
C15: E
C16: F
C17: E
C18: F
C19: E
C20: F
C21: E
... C71: E
A72: Total | D72: =SUM(D34,D32,D30,D28,D26,D24,D22,D20,D18,D16,D14,D12,D10) -> 49 | E72: =SUM(E10,E12,E16,E18,E20,E22,E24,E26,E14,E28,E32,E34,E36,E38,E40,E42,E44,E46,E48,E50,E52,E54,E56,E58,E60,E62,E64,E66,E68,E70) -> 0 | F72: =SUM(F34,F32,F30,F28,F26,F24,F22,F20,F18,F16,F14,F12,F10) -> 147 | G72: =SUM(G10,G12,G16,G18,G20,G22,G24,G26,G14,G28,G32,G34,G36,G38,G40,G42,G44,G46,G48,G50,G52,G54,G56,G58,G60,G62,G64,G66,G68,G70) -> 0 | H72: =SUM(H34,H32,H30,H28,H26,H24,H22,H20,H18,H16,H14,H12,H10) -> 28 | I72: =SUM(I10,I12,I16,I18,I20,I22,I24,I26,I14,I28,I32,I34,I36,I38,I40,I42,I44,I46,I48,I50,I52,I54,I56,I58,I60,I62,I64,I66,I68,I70) -> 0 | J72: =SUM(J34,J32,J30,J28,J26,J24,J22,J20,J18,J16,J14,J12,J10) -> 132 | K72: =SUM(K10,K12,K16,K18,K20,K22,K24,K26,K14,K28,K32,K34,K36,K38,K40,K42,K44,K46,K48,K50,K52,K54,K56,K58,K60,K62,K64,K66,K68,K70) -> 0 | L72: =SUM(L10,L12,L16,L18,L20,L22,L24,L26,L14,L28,L32,L34,L36,L38,L40,L42,L44,L46,L48,L50,L52,L54,L56,L58,L60,L62,L64,L66,L68,L70) -> 0 | M72: =SUM(M10,M12,M16,M18,M20,M22,M24,M26,M14,M28,M32,M34,M36,M38,M40,M42,M44,M46,M48,M50,M52,M54,M56,M58,M60,M62,M64,M66,M68,M70) -> 0 | N72: =SUM(N10,N12,N16,N18,N20,N22,N24,N26,N14,N28,N32,N34,N36,N38,N40,N42,N44,N46,N48,N50,N52,N54,N56,N58,N60,N62,N64,N66,N68,N70) -> 0 | O72: =SUM(O10,O12,O16,O18,O20,O22,O24,O26,O14,O28,O32,O34,O36,O38,O40,O42,O44,O46,O48,O50,O52,O54,O56,O58,O60,O62,O64,O66,O68,O70) -> 0
D73: =SUM(D35,D33,D31,D29,D27,D25,D23,D21,D19,D17,D15,D13,D11) -> 0 | E73: =SUM(E11,E13,E17,E19,E21,E23,E25,E27,E15,E29,E33,E35,E37,E39,E41,E43,E45,E47,E49,E51,E53,E55,E57,E59,E61,E63,E65,E67,E69,E71) -> 0 | F73: =SUM(F35,F33,F31,F29,F27,F25,F23,F21,F19,F17,F15,F13,F11) -> 0 | G73: =SUM(G11,G13,G17,G19,G21,G23,G25,G27,G15,G29,G33,G35,G37,G39,G41,G43,G45,G47,G49,G51,G53,G55,G57,G59,G61,G63,G65,G67,G69,G71) -> 0 | H73: =SUM(H11,H13,H17,H19,H21,H23,H25,H27,H15,H29,H33,H35,H37,H39,H41,H43,H45,H47,H49,H51,H53,H55,H57,H59,H61,H63,H65,H67,H69,H71) -> 0 | I73: =SUM(I11,I13,I17,I19,I21,I23,I25,I27,I15,I29,I33,I35,I37,I39,I41,I43,I45,I47,I49,I51,I53,I55,I57,I59,I61,I63,I65,I67,I69,I71) -> 0 | J73: =SUM(J11,J13,J17,J19,J21,J23,J25,J27,J15,J29,J33,J35,J37,J39,J41,J43,J45,J47,J49,J51,J53,J55,J57,J59,J61,J63,J65,J67,J69,J71) -> 0 | K73: =SUM(K11,K13,K17,K19,K21,K23,K25,K27,K15,K29,K33,K35,K37,K39,K41,K43,K45,K47,K49,K51,K53,K55,K57,K59,K61,K63,K65,K67,K69,K71) -> 0 | L73: =SUM(L11,L13,L17,L19,L21,L23,L25,L27,L15,L29,L33,L35,L37,L39,L41,L43,L45,L47,L49,L51,L53,L55,L57,L59,L61,L63,L65,L67,L69,L71) -> 0 | M73: =SUM(M11,M13,M17,M19,M21,M23,M25,M27,M15,M29,M33,M35,M37,M39,M41,M43,M45,M47,M49,M51,M53,M55,M57,M59,M61,M63,M65,M67,M69,M71) -> 0 | N73: =SUM(N11,N13,N17,N19,N21,N23,N25,N27,N15,N29,N33,N35,N37,N39,N41,N43,N45,N47,N49,N51,N53,N55,N57,N59,N61,N63,N65,N67,N69,N71) -> 0 | O73: =SUM(O11,O13,O17,O19,O21,O23,O25,O27,O15,O29,O33,O35,O37,O39,O41,O43,O45,O47,O49,O51,O53,O55,O57,O59,O61,O63,O65,O67,O69,O71) -> 0
A75: Remarks : Discharging | H75: Remarks : Loading
A90: CHIEF CHECKER | J90: CHIEF OFFICER

Sheet Time Sheet
A1: GREEN MARINE CO., LTD.
A2: PYEONGTAEK, KOREA
C3: T I M E S H E E T
A6: M / V : | C6: VOY # : | G6: DATE : | H6: ='Final Work'!선적종료일 -> 46219
A8: PIER : | C8: BERTH : | G8: WEATHER :
H10: PORT : PYEONGTAEK, KOREA
A12: T I M E | C12: R E M A R K S
A41: CHIEF CHECKER

Sheet OS-IN
A1: GREEN MARINE CO., LTD.
A2: PYEONGTAEK, KOREA
A4: CARGO OVERAGE & SHORTAGE REPORT (DISCH)
A6: M / V : | B6: YOKOHAMA TRADER | G6: VOY. NO.: | K6: DATE :
A8: PORT : | B8: PYEONGTAEK, KOREA | G8: PIER : | K8: BERTH :
A10: B/L NO. | B10: MARKS (PORT) | D10: DESCRIPTION | G10: TYPE OF | H10: MANIFESTED | J10: DISCHARGED | K10: OVER | L10: SHORT | M10: REMARKS
G11: PKGS
D19: T O T A L | G19: VAN | H19: =SUM(H12:I18) -> 196 | J19: =SUM(J12:J18) -> 196 | K19: NIL | L19: NIL
A28: REMARKS
A39: CHIEF CHECKER | G39: STEVEDORE PCTC | L39: CHIEF OFFICER

Sheet DM-IN
A1: GREEN MARINE CO., LTD.
A2: PYEONGTAEK, KOREA
A4: CARGO DAMAGE REPORT
A6: M / V : | B6: ='Final Work'!모선이름 -> YOKOHAMA TRADER | H6: VOY. NO. : | J6: ='OS-IN'!H6 -> 2611E | O6: DATE : | P6: ='OS-IN'!L6 -> 46219
A8: PORT : | B8: PYEONGTAEK, KOREA | H8: PIER : | J8: PCTC | O8: BERTH : | P8: ='Final Work'!G6 -> 8
A10: PORT | B10: B/L NO. | C10: MARKS | F10: CONTENTS | J10: NO. OF | K10: TYPE | L10: EXCEPTION ( Found In Stow )
J11: PKGS
A32: CHIEF CHECKER | I32: STEVEDORE PCTC | O32: CHIEF OFFICER

Sheet OS-OUT
A1: GREEN MARINE CO., LTD.
A2: PYEONGTAEK, KOREA
A4: CARGO OVERAGE & SHORTAGE REPORT (LOAD)
A6: M / V : | B6: YOKOHAMA TRADER | G6: VOY. NO.: | K6: DATE :
A8: PORT : | B8: PYEONGTAEK, KOREA | G8: PIER : | K8: BERTH :
A10: B/L NO. | B10: MARKS (PORT) | D10: DESCRIPTION | G10: TYPE OF | H10: MANIFESTED | J10: LOADED | K10: OVER | L10: SHORT | M10: REMARKS
G11: PKGS
D15: T O T A L | G15: VAN | H15: =SUM(H10:I14) -> 160 | J15: =SUM(J10:J14) -> 160 | K15: NIL | L15: NIL
A27: REMARKS
A37: CHIEF CHECKER | G37: STEVEDORE PCTC | L37: CHIEF OFFICER

Sheet DM-OUT
A1: GREEN MARINE CO., LTD.
A2: PYEONGTAEK, KOREA
A4: CARGO DAMAGE REPORT
A6: M / V : | B6: ='Final Work'!모선이름 -> YOKOHAMA TRADER | H6: VOY. NO. : | J6: ='OS-OUT'!H6 -> 2612W | O6: DATE : | P6: ='Final Work'!L4 -> 46219
A8: PORT : | B8: PYEONGTAEK, KOREA | H8: PIER : | J8: PCTC | O8: BERTH : | P8: ='Final Work'!작업선석 -> 8
A10: PORT | B10: B/L NO. | C10: MARKS | F10: CONTENTS | J10: NO. OF | K10: TYPE | L10: EXCEPTION ( Prior To Load )
J11: PKGS
A32: CHIEF CHECKER | I32: STEVEDORE PCTC | O32: CHIEF OFFICER

Sheet DAMAGE-EACH
A1: GREEN MARINE CO., LTD.
A2: PYEONGTAEK, KOREA
A4: CONTAINER DAMAGED REPORT
A6: M / V : | B6: ='Final Work'!모선이름 -> YOKOHAMA TRADER | F6: VOY. NO. : | H6: =[0]!양하항차 -> #REF! | J6: DATE : | K6: =#REF! -> #REF!
A8: CONTAINER NO : | F8: SEAL NO. : | J8: SIZE : | K8: 20' | L8: 40' | M8: HC'
A9: OPERATOR :
M10: PORT : PYEONGTAEK, KOREA
A33: Description of Damage :
B34: ( Found in stow )
A41: SYMBOLS
A42: B | B42: BO | C42: BU | D42: C | E42: D | F42: DO | G42: H | H42: M | I42: O | J42: P | K42: R | L42: S | M42: T
A43: Broken | B43: Bulged out | C43: Buckled | D43: Cut | E43: Dent | F43: Distorted | G43: Hole | H43: Miss | I43: Burned out | J43: Patch | K43: Rusty | L43: Scratch | M43: Torn
A53: CHIEF CHECKER | F53: STEVEDORE | K53: CHIEF OFFICER
A54: GREEN MARINE CO., LTD.
A55: PYEONGTAEK, KOREA
A57: CONTAINER DAMAGED REPORT
A59: M / V : | B59: ='Final Work'!모선이름 -> YOKOHAMA TRADER | F59: VOY. NO. : | H59: =#REF! -> #REF! | J59: DATE : | K59: =#REF! -> #REF!
A61: CONTAINER NO : | F61: SEAL NO. : | J61: SIZE : | K61: 20' | L61: 40' | M61: HC'
A62: OPERATOR :
M63: PORT : PYEONGTAEK, KOREA
A86: Description of Damage :
B87: ( Found in stow )
A93: SYMBOLS
A94: B | B94: BO | C94: BU | D94: C | E94: D | F94: DO | G94: H | H94: M | I94: O | J94: P | K94: R | L94: S | M94: T
A95: Broken | B95: Bulged out | C95: Buckled | D95: Cut | E95: Dent | F95: Distorted | G95: Hole | H95: Miss | I95: Burned out | J95: Patch | K95: Rusty | L95: Scratch | M95: Torn
A105: CHIEF CHECKER | F105: STEVEDORE | K105: CHIEF OFFICER

Sheet Act. Cntr-Seal No List
A1: GREEN MARINE CO., LTD.
A2: PYEONGTAEK, KOREA
A4: M / V : | B4: ='Final Work'!B4 -> YOKOHAMA TRADER | F4: DATE :
A6: VOY # : | B6: ='OS-IN'!H6 -> 2611E | F6: PORT : | G6: PYEONGTAEK, KOREA
B8: ACTUAL CONTAINER & SEAL NUMBER LIST
H9: DISCH'
A10: MANIFEST | D10: SIZE | E10: ACTUAL | G10: RESEAL NO. | H10: REMARKS
A11: CONT'R NO. | C11: SEAL NO. | E11: CONT'R NO. | F11: SEAL NO.
A33: 20FT | B33: FULL
B34: EMPTY
A35: 40FT | B35: FULL | C35: 1
B36: EMPTY
A37: TOTAL | C37: =SUM(C33:C36) -> 1 | G37: CHIEF CHECKER
A38: GREEN MARINE CO., LTD.
A39: PYEONGTAEK, KOREA
A41: M / V : | B41: =모선이름 -> YOKOHAMA TRADER | F41: DATE : | G41: ='Final Work'!L4 -> 46219
A43: VOY # : | B43: ='OS-OUT'!H6 -> 2612W | F43: PORT : | G43: PYEONGTAEK, KOREA
B45: ACTUAL CONTAINER & SEAL NUMBER LIST
H46: LOAD'
A47: MANIFEST | D47: SIZE | E47: ACTUAL | G47: RESEAL NO. | H47: REMARKS
A48: CONT'R NO. | C48: SEAL NO. | E48: CONT'R NO. | F48: SEAL NO.
A49: -NIL-
A70: 20FT | B70: FULL
B71: EMPTY
A72: 40FT | B72: FULL
B73: EMPTY
A74: TOTAL | C74: =SUM(C70:C73) -> 0 | G74: CHIEF CHECKER

Sheet RF Condition Report
A1: GREEN MARINE CO., LTD.
A2: PYEONGTAEK, KOREA
A4: REEFER CONTAINER CONDITION REPORT
A5: Discharging / Loading
I6: ( 1/1 )
A7: M / V : YOKOHAMA TRADER | D7: VOY # : | E7: ='OS-IN'!H6 -> 2611E | G7: DATE : | H7: ='OS-IN'!L6 -> 46219
A8: PIER : PCTC | D8: BERTH : | E8: ='Final Work'!작업선석 -> 8 | G8: PORT : | H8: PYEONGTAEK, KOREA
A10: CONTAINER NO. | B10: SEAL NO. | C10: SIZE | D10: LOCATION | F10: TEMPERATURE | H10: TIME | I10: REMARKS
D11: Bay/Slot/Tier | F11: Setting | G11: Actual | H11: Plug In / Out
A48: CHIEF CHECKER | D48: STEVEDORE PCTC | H48: CHIEF OFFICER
A49: GREEN MARINE CO., LTD.
A50: PYEONGTAEK, KOREA
A52: REEFER CONTAINER CONDITION REPORT
A53: Discharging / Loading
I54: ( 1/1 )
A55: =모선이름 -> M / V : YOKOHAMA TRADER | D55: VOY # : | E55: ='OS-OUT'!H6 -> 2612W | G55: DATE : | H55: ='Final Work'!L4 -> 46219
A56: PIER : PCTC | D56: BERTH : | E56: ='Final Work'!작업선석 -> 8 | G56: PORT : | H56: PYEONGTAEK, KOREA
A58: CONTAINER NO. | B58: SEAL NO. | C58: SIZE | D58: LOCATION | F58: TEMPERATURE | H58: TIME | I58: REMARKS
D59: Bay/Slot/Tier | F59: Setting | G59: Actual | H59: Plug In / Out
A60: FBIU5370460 | C60: RH | F60: -18 | G60: -15.3 | H60: 09:10 HR'S | I60: SKR
A61: FSCU5891089 | C61: RH | F61: -18 | G61: -15.5 | H61: 〃 | I61: SKR
A62: OTPU6564375 | C62: RH | F62: -18 | G62: -15.4 | H62: 〃 | I62: DJS
A63: OTPU6564591 | C63: RH | F63: -18 | G63: -16.3 | H63: 〃 | I63: DJS
A64: OTPU6565854 | C64: RH | F64: -18 | G64: -18 | H64: 〃 | I64: DJS
A65: OTPU6566594 | C65: RH | F65: -18 | G65: -17.8 | H65: 〃 | I65: DJS
A66: SEKU9295694 | C66: RH | F66: -18 | G66: -18.6 | H66: 〃 | I66: DJS
A67: SEKU9302155 | C67: RH | F67: -18 | G67: -19 | H67: 〃 | I67: DJS
A68: SEKU9304800 | C68: RH | F68: -18 | G68: -17.4 | H68: 〃 | I68: DJS
A69: SEKU9305093 | C69: RH | F69: -18 | G69: -18.6 | H69: 〃 | I69: DJS
A70: SEKU9305982 | C70: RH | F70: -18 | G70: -17.7 | H70: 〃 | I70: DJS
A71: SEKU9306232 | C71: RH | F71: -18 | G71: -15 | H71: 〃 | I71: DJS
... A74: SKRU9500654 | C74: RH | F74: -18 | G74: -15.5 | H74: 〃 | I74: SKR
A91: < CY 보관지침 >
A92: 1. 최초 화주로 부터 지정된 온도(SETTING 온도를 말하며 수입목록 혹은 BAY PLAN에
A93: 표기된 온도)는 그 적정 온도를 유지하고 있는지 4시간마다 확인하여 기록 보관해야한다.
A94: 2. 온도를 지정하는 지시 및 표기가 없을 경우 일반적으로 채용되고 있는
A95: 냉동/냉장 화물의 운송온도를 기준으로 한다.
A96: 3. 만일 온도 이상 및 기타 기기의 이상이 발견될 시는 즉시 OPERATOR에게 통보하여야한다.
A101: CHIEF CHECKER | D101: STEVEDORE PCTC | H101: CHIEF OFFICER

Sheet Performance
A1: GREEN MARINE CO., LTD
A2: PYEONGTAEK, KOREA
A4: PERFORMANCE REPORT
A6: M / V : | D6: ='Final Work'!B4 -> YOKOHAMA TRADER | O6: VOY # : | R6: ='Final Work'!G4 -> 2611E & 2612W | Y6: DATE : | AB6: ='Final Work'!L4 -> 46219
A8: PIER : | D8: PCTC | O8: BERTH : | R8: ='Final Work'!G6 -> 8 | Y8: PORT : | AB8: PYEONGTAEK, KOREA
A10: Status | H10: FULL | P10: EMPTY | X10: TOTAL | AA10: REMARKS
A11: Description | H11: 20' | J11: 40' | L11: HC | N11: 45' | P11: 20' | R11: 40' | T11: HC | V11: 45'
A12: IN BOUND | X12: =SUM(H12:W12) -> 100
X13: =SUM(H13:W13) -> 47 | AA13: RH x 3
X14: =SUM(H14:W14) -> 5
X15: =SUM(H15:W15) -> 38 | AA15: RH x 6
X16: =SUM(H16:W16) -> 6
X17: =SUM(H17:W17) -> 0
X18: =SUM(H18:W18) -> 0
D19: S-TOTAL | H19: =SUM(H12:I18) -> 49 | J19: =SUM(J12:K18) -> 0 | L19: =SUM(L12:M18) -> 147 | N19: =SUM(N12:O18) -> 0 | P19: =SUM(P12:Q18) -> 0 | R19: =SUM(R12:S18) -> 0 | T19: =SUM(T12:U18) -> 0 | V19: =SUM(V12:W18) -> 0 | X19: =SUM(X12:Z18) -> 196
A20: OUT BOUND | X20: =SUM(H20:W20) -> 81 | AA20: RH x 3 , 40'DG x 2
X21: =SUM(H21:W21) -> 28
X22: =SUM(H22:W22) -> 6
X23: =SUM(H23:W23) -> 39 | AA23: RH x 12
X24: =SUM(H24:W24) -> 6
X25: =SUM(H25:W25) -> 0
X26: =SUM(H26:W26) -> 0
D27: S-TOTAL | H27: =SUM(H20:I26) -> 28 | J27: =SUM(J20:K26) -> 0 | L27: =SUM(L20:M26) -> 132 | N27: =SUM(N20:O26) -> 0 | P27: =SUM(P20:Q26) -> 0 | R27: =SUM(R20:S26) -> 0 | T27: =SUM(T20:U26) -> 0 | V27: =SUM(V20:W26) -> 0 | X27: =SUM(X20:Z26) -> 160
A28: SHIFT | D28: 1 TIME
D29: 1 TIME
A30: GRAND TOTAL | H30: =SUM(H19+H27+H28+H29) -> 77 | J30: =SUM(J19+J27+J28+J29) -> 0 | L30: =SUM(L19+L27+L28+L29) -> 279 | N30: =SUM(N19+N27+N28+N29) -> 0 | P30: =SUM(P19+P27+P28+P29) -> 0 | R30: =SUM(R19+R27+R28+R29) -> 0 | T30: =SUM(T19+T27+T28+T29) -> 0 | V30: =SUM(V19+V27+V28+V29) -> 0 | X30: =SUM(X19+X27+X28+X29) -> 356
A32: # WORKING PERIOD
A34: CRANE NO. | E34: FROM | K34: TO | Q34: HOURS | W34: REMARKS
A35: #1 (G/C) | E35: 0.0625 | Q35: =IF(AND(NOT(ISBLANK(K35)),NOT(ISBLANK(E35))), IF(K35>E35,K35-E35,24-E35+K35), "") | W35: COMMENCED DISCH.
E36: =E35 -> 0.0625 | K36: 0.14583333 | Q36: =IF(AND(NOT(ISBLANK(K36)),NOT(ISBLANK(E36))), IF(K36>E36,K36-E36,24-E36+K36), "") -> 0.083333333 | W36: DISCH. OF CONT'R
E37: =K36 -> 0.14583333 | K37: 0.16666667 | Q37: =IF(AND(NOT(ISBLANK(K37)),NOT(ISBLANK(E37))), IF(K37>E37,K37-E37,24-E37+K37), "") -> 0.020833333 | W37: TEA TIME
E38: =K37 -> 0.16666667 | K38: 0.21875 | Q38: =IF(AND(NOT(ISBLANK(K38)),NOT(ISBLANK(E38))), IF(K38>E38,K38-E38,24-E38+K38), "") -> 0.052083333 | W38: DISCH. OF CONT'R
K39: =K38 -> 0.21875 | Q39: =IF(AND(NOT(ISBLANK(K39)),NOT(ISBLANK(E39))), IF(K39>E39,K39-E39,24-E39+K39), "") | W39: COMPLETED DISCH.
E40: 0.22222222 | Q40: =IF(AND(NOT(ISBLANK(K40)),NOT(ISBLANK(E40))), IF(K40>E40,K40-E40,24-E40+K40), "") | W40: COMMENCED LOAD.
E41: =E40 -> 0.22222222 | K41: 0.27083333 | Q41: =IF(AND(NOT(ISBLANK(K41)),NOT(ISBLANK(E41))), IF(K41>E41,K41-E41,24-E41+K41), "") -> 0.048611111 | W41: LOAD. OF CONT'R
E42: =K41 -> 0.27083333 | K42: 0.33333333 | Q42: =IF(AND(NOT(ISBLANK(K42)),NOT(ISBLANK(E42))), IF(K42>E42,K42-E42,24-E42+K42), "") -> 0.0625 | W42: MEAL TIME
E43: =K42 -> 0.33333333 | K43: 0.39583333 | Q43: =IF(AND(NOT(ISBLANK(K43)),NOT(ISBLANK(E43))), IF(K43>E43,K43-E43,24-E43+K43), "") -> 0.0625 | W43: LOAD. OF CONT'R
K44: =K43 -> 0.39583333 | Q44: =IF(AND(NOT(ISBLANK(K44)),NOT(ISBLANK(E44))), IF(K44>E44,K44-E44,24-E44+K44), "") | W44: COMPLETED LOAD. & GANG K/OFF
Q45: =IF(AND(NOT(ISBLANK(K45)),NOT(ISBLANK(E45))), IF(K45>E45,K45-E45,24-E45+K45), "")
Q46: =IF(AND(NOT(ISBLANK(K46)),NOT(ISBLANK(E46))), IF(K46>E46,K46-E46,24-E46+K46), "")
...
