Workbook

Sheet Final Work
A1: GREEN MARINE CO., LTD.
B2: FINAL WORKING REPORT (VOUCHER)
A4: M/V : | B4: DONGJIN CONTINENTAL | F4: VOY # : | K4: DATE :
A6: PIER : | F6: BERTH : | K6: PORT : | L6: PYEONGTAEK, KOREA
A8: OPERATOR | B8: PORT | C8: FULL / EMPTY | D8: =+"DISCH ("&D74+E74+F74+G74+D75+E75+F75+G75&")" -> DISCH (170) | H8: =+"LOAD ("&H74+I74+J74+K74+H75+I75+J75+K75&")" -> LOAD (216) | L8: =+"SHIFT ("&L74+M74+N74+O74+L75+M75+N75+O75&")" -> SHIFT (2)
D9: 20' | E9: 40' | F9: HC | G9: 45' | H9: 20' | I9: 40' | J9: HC | K9: 45' | L9: 20' | M9: 40' | N9: HC | O9: 45'
C10: F
C11: E
C12: F
C13: E
C14: F
C15: E
C16: F
C17: E
C18: F
C19: E
C20: F
C21: E
... C73: E
A74: Total | D74: =SUM(D38,D36,D34,D32,D30,D28,D26,D24,D22,D20,D18,D16,D14,D12,D10) -> 40 | E74: =SUM(E10,E12,E14,E16,E20,E22,E24,E28,E30,E34,E38,E40,E42,E44,E18,E36,E46,E48,E50,E52,E54,E56,E58,E60,E62,E64,E66,E68,E70,E72) -> 0 | F74: =SUM(F38,F36,F34,F32,F30,F28,F26,F24,F22,F20,F18,F16,F14,F12,F10) -> 110 | G74: =SUM(G10,G12,G14,G16,G20,G22,G24,G28,G30,G34,G38,G40,G42,G44,G18,G36,G46,G48,G50,G52,G54,G56,G58,G60,G62,G64,G66,G68,G70,G72) -> 0 | H74: =SUM(H38,H36,H34,H32,H30,H28,H26,H24,H22,H20,H18,H16,H14,H12,H10) -> 47 | I74: =SUM(I10,I12,I14,I16,I20,I22,I24,I28,I30,I34,I38,I40,I42,I44,I18,I36,I46,I48,I50,I52,I54,I56,I58,I60,I62,I64,I66,I68,I70,I72) -> 0 | J74: =SUM(J38,J36,J34,J32,J30,J28,J26,J24,J22,J20,J18,J16,J14,J12,J10) -> 169 | K74: =SUM(K10,K12,K14,K16,K20,K22,K24,K28,K30,K34,K38,K40,K42,K44,K18,K36,K46,K48,K50,K52,K54,K56,K58,K60,K62,K64,K66,K68,K70,K72) -> 0 | L74: =SUM(L10,L12,L14,L16,L20,L22,L24,L28,L30,L34,L38,L40,L42,L44,L18,L36,L46,L48,L50,L52,L54,L56,L58,L60,L62,L64,L66,L68,L70,L72) -> 2 | M74: =SUM(M10,M12,M14,M16,M20,M22,M24,M28,M30,M34,M38,M40,M42,M44,M18,M36,M46,M48,M50,M52,M54,M56,M58,M60,M62,M64,M66,M68,M70,M72) -> 0 | N74: =SUM(N10,N12,N14,N16,N20,N22,N24,N28,N30,N34,N38,N40,N42,N44,N18,N36,N46,N48,N50,N52,N54,N56,N58,N60,N62,N64,N66,N68,N70,N72) -> 0 | O74: =SUM(O10,O12,O14,O16,O20,O22,O24,O28,O30,O34,O38,O40,O42,O44,O18,O36,O46,O48,O50,O52,O54,O56,O58,O60,O62,O64,O66,O68,O70,O72) -> 0
D75: =SUM(D39,D37,D35,D33,D31,D29,D27,D25,D23,D21,D19,D17,D15,D13,D11) -> 20 | E75: =SUM(E11,E13,E15,E17,E21,E23,E27,E29,E31,E35,E39,E41,E43,E45,E19,E37,E47,E49,E51,E53,E55,E57,E59,E61,E63,E65,E67,E69,E71,E73) -> 0 | F75: =SUM(F39,F37,F35,F33,F31,F29,F27,F25,F23,F21,F19,F17,F15,F13,F11) -> 0 | G75: =SUM(G11,G13,G15,G17,G21,G23,G27,G29,G31,G35,G39,G41,G43,G45,G19,G37,G47,G49,G51,G53,G55,G57,G59,G61,G63,G65,G67,G69,G71,G73) -> 0 | H75: =SUM(H39,H37,H35,H33,H31,H29,H27,H25,H23,H21,H19,H17,H15,H13,H11) -> 0 | I75: =SUM(I11,I13,I15,I17,I21,I23,I27,I29,I31,I35,I39,I41,I43,I45,I19,I37,I47,I49,I51,I53,I55,I57,I59,I61,I63,I65,I67,I69,I71,I73) -> 0 | J75: =SUM(J39,J37,J35,J33,J31,J29,J27,J25,J23,J21,J19,J17,J15,J13,J11) -> 0 | K75: =SUM(K11,K13,K15,K17,K21,K23,K27,K29,K31,K35,K39,K41,K43,K45,K19,K37,K47,K49,K51,K53,K55,K57,K59,K61,K63,K65,K67,K69,K71,K73) -> 0 | L75: =SUM(L11,L13,L15,L17,L21,L23,L27,L29,L31,L35,L39,L41,L43,L45,L19,L37,L47,L49,L51,L53,L55,L57,L59,L61,L63,L65,L67,L69,L71,L73) -> 0 | M75: =SUM(M11,M13,M15,M17,M21,M23,M27,M29,M31,M35,M39,M41,M43,M45,M19,M37,M47,M49,M51,M53,M55,M57,M59,M61,M63,M65,M67,M69,M71,M73) -> 0 | N75: =SUM(N11,N13,N15,N17,N21,N23,N27,N29,N31,N35,N39,N41,N43,N45,N19,N37,N47,N49,N51,N53,N55,N57,N59,N61,N63,N65,N67,N69,N71,N73) -> 0 | O75: =SUM(O11,O13,O15,O17,O21,O23,O27,O29,O31,O35,O39,O41,O43,O45,O19,O37,O47,O49,O51,O53,O55,O57,O59,O61,O63,O65,O67,O69,O71,O73) -> 0
A77: Remarks : Discharging | H77: Remarks : Loading
A87: CHIEF CHECKER | K87: CHIEF OFFICER

Sheet Time Sheet
A1: GREEN MARINE CO., LTD.
A2: PYEONGTAEK, KOREA
C3: T I M E S H E E T
A6: M / V : | C6: VOY # : | G6: DATE : | H6: ='Final Work'!선적종료일 -> 46222
A8: PIER : | C8: BERTH : | G8: WEATHER :
H10: PORT : PYEONGTAEK, KOREA
A12: T I M E | C12: R E M A R K S
A46: CHIEF CHECKER

Sheet OS-IN
A1: GREEN MARINE CO., LTD.
A2: PYEONGTAEK, KOREA
A4: CARGO OVERAGE & SHORTAGE REPORT (DISCH)
A6: M / V : | B6: DONGJIN CONTINENTAL | G6: VOY. NO.: | K6: DATE :
A8: PORT : | B8: PYEONGTAEK, KOREA | G8: PIER : | K8: BERTH :
A10: B/L NO. | B10: MARKS (PORT) | D10: DESCRIPTION | G10: TYPE OF | H10: MANIFESTED | J10: DISCHARGED | K10: OVER | L10: SHORT | M10: REMARKS
G11: PKGS
D19: T O T A L | G19: VAN | H19: =SUM(H11:I18) -> 170 | J19: =SUM(J11:J18) -> 170 | K19: NIL | L19: NIL
A28: REMARKS
A39: CHIEF CHECKER | G39: STEVEDORE PCTC | L39: CHIEF OFFICER

Sheet DM-IN
A1: GREEN MARINE CO., LTD.
A2: PYEONGTAEK, KOREA
A4: CARGO DAMAGE REPORT
A6: M / V : | B6: DONGJIN CONTINENTAL | H6: VOY. NO. : | J6: ='OS-IN'!H6 -> 0220E | O6: DATE : | P6: ='OS-IN'!L6 -> 46222
A8: PORT : | B8: PYEONGTAEK, KOREA | H8: PIER : | J8: PCTC | O8: BERTH : | P8: ='Final Work'!G6 -> 6
A10: PORT | B10: B/L NO. | C10: MARKS | F10: CONTENTS | J10: NO. OF | K10: TYPE | L10: EXCEPTION ( Found In Stow )
J11: PKGS
A32: CHIEF CHECKER | I32: STEVEDORE PCTC | O32: CHIEF OFFICER

Sheet OS-OUT
A1: GREEN MARINE CO., LTD.
A2: PYEONGTAEK, KOREA
A4: CARGO OVERAGE & SHORTAGE REPORT (LOAD)
A6: M / V : | B6: DONGJIN CONTINENTAL | G6: VOY. NO.: | K6: DATE :
A8: PORT : | B8: PYEONGTAEK, KOREA | G8: PIER : | K8: BERTH :
A10: B/L NO. | B10: MARKS (PORT) | D10: DESCRIPTION | G10: TYPE OF | H10: MANIFESTED | J10: LOADED | K10: OVER | L10: SHORT | M10: REMARKS
G11: PKGS
D15: T O T A L | G15: VAN | H15: =SUM(H10:I14) -> 216 | J15: =SUM(J10:J14) -> 216 | K15: NIL | L15: NIL
A27: REMARKS
A37: CHIEF CHECKER | G37: STEVEDORE PCTC | L37: CHIEF OFFICER

Sheet DM-OUT
A1: GREEN MARINE CO., LTD.
A2: PYEONGTAEK, KOREA
A4: CARGO DAMAGE REPORT
A6: M / V : | B6: DONGJIN CONTINENTAL | H6: VOY. NO. : | J6: ='OS-OUT'!H6 -> 0221W | O6: DATE : | P6: ='Final Work'!L4 -> 46222
A8: PORT : | B8: PYEONGTAEK, KOREA | H8: PIER : | J8: PCTC | O8: BERTH : | P8: ='Final Work'!G6 -> 6
A10: PORT | B10: B/L NO. | C10: MARKS | F10: CONTENTS | J10: NO. OF | K10: TYPE | L10: EXCEPTION ( Prior To Load )
J11: PKGS
A32: CHIEF CHECKER | I32: STEVEDORE PCTC | O32: CHIEF OFFICER

Sheet Act. Cntr-Seal No List
A1: GREEN MARINE CO., LTD.
A2: PYEONGTAEK, KOREA
A4: M / V : DONGJIN CONTINENTAL | F4: DATE :
A6: VOY.NO.: 0220E | F6: PORT : | G6: PYEONGTAEK, KOREA
C8: ACTUAL CONTAINER & SEAL NUMBER LIST
H9: DISCH'
A10: MANIFEST | D10: SIZE | E10: ACTUAL | G10: RESEAL NO. | H10: REMARKS
A11: CONT'R NO. | C11: SEAL NO. | E11: CONT'R NO. | F11: SEAL NO.
A33: 20FT | B33: EMPTY
B34: FULL
A35: 40FT | B35: EMPTY
B36: FULL | C36: 1
A37: TOTAL | C37: =SUM(C33:C36) -> 1 | G37: CHIEF CHECKER
A38: GREEN MARINE CO., LTD.
A39: PYEONGTAEK, KOREA
A41: M / V : DONGJIN CONTINENTAL | F41: DATE : | G41: ='Final Work'!L4 -> 46222
A43: VOY.NO.: 0221W | F43: PORT : | G43: PYEONGTAEK, KOREA
C45: ACTUAL CONTAINER & SEAL NUMBER LIST
H46: LOAD'
A47: MANIFEST | D47: SIZE | E47: ACTUAL | G47: RESEAL NO. | H47: REMARKS
A48: CONT'R NO. | C48: SEAL NO. | E48: CONT'R NO. | F48: SEAL NO.
A70: 20FT | B70: EMPTY
B71: FULL
A72: 40FT | B72: EMPTY
B73: FULL
A74: TOTAL | C74: =SUM(C70:C73) -> 0 | G74: CHIEF CHECKER

Sheet RF condition report
A1: GREEN MARINE CO., LTD.
A2: PYEONGTAEK, KOREA
A4: REEFER CONTAINER CONDITION REPORT
A5: Discharging / Loading
I6: ( 1/1)
A7: M / V : DONGJIN CONTINENTAL | D7: VOY # : | E7: ='OS-IN'!H6 -> 0220E | G7: DATE : | H7: ='OS-IN'!L6 -> 46222
A8: PIER : PCTC | D8: BERTH : | E8: ='Final Work'!G6 -> 6 | G8: PORT : | H8: PYEONGTAEK, KOREA
A10: CONTAINER NO. | B10: SEAL NO. | C10: SIZE | D10: LOCATION | F10: TEMPERATURE | H10: TIME | I10: REMARKS
D11: Bay/Slot/Tier | F11: Setting | G11: Actual | H11: Plug In / Out
A43: CHIEF CHECKER | D43: STEVEDORE PCTC | H43: CHIEF OFFICER
A44: GREEN MARINE CO., LTD.
A45: PYEONGTAEK, KOREA
A47: REEFER CONTAINER CONDITION REPORT
A48: Discharging / Loading
I49: ( 1/1)
A50: M / V : DONGJIN CONTINENTAL | D50: VOY # : | E50: ='OS-OUT'!H6 -> 0221W | G50: DATE : | H50: ='Final Work'!L4 -> 46222
A51: PIER : PCTC | D51: BERTH : | E51: ='Final Work'!G6 -> 6 | G51: PORT : | H51: PYEONGTAEK, KOREA
A53: CONTAINER NO. | B53: SEAL NO. | C53: SIZE | D53: LOCATION | F53: TEMPERATURE | H53: TIME | I53: REMARKS
D54: Bay/Slot/Tier | F54: Setting | G54: Actual | H54: Plug In / Out
A55: DJLU5900171 | C55: 40'RH | F55: -18 | G55: -17.2 | H55: 17:00 HR'S | I55: DJS
A56: FBIU5370454 | C56: 40'RH | F56: -18 | G56: -17.9 | H56: " | I56: SKR
A57: FSCU5869357 | C57: 40'RH | F57: 3 | G57: 3 | H57: " | I57: SKR
A58: OTPU6565999 | C58: 40'RH | F58: -18 | G58: -18.2 | H58: " | I58: DJS
A59: OTPU6671584 | C59: 40'RH | F59: -18 | G59: -18.3 | H59: " | I59: DJS
A60: OTPU6671706 | C60: 40'RH | F60: -18 | G60: -17.6 | H60: " | I60: DJS
A61: OTPU6765169 | C61: 40'RH | F61: -18 | G61: -17.9 | H61: " | I61: DJS
A62: OTPU6776543 | C62: 40'RH | F62: -18 | G62: -18.6 | H62: " | I62: DJS
A63: OTPU6776672 | C63: 40'RH | F63: -18 | G63: -18 | H63: " | I63: DJS
A64: SEKU9295776 | C64: 40'RH | F64: -18 | G64: -18.4 | H64: " | I64: DJS
A65: SEKU9305215 | C65: 40'RH | F65: -18 | G65: -18.4 | H65: " | I65: DJS
A66: SEKU9305257 | C66: 40'RH | F66: -18 | G66: -18.2 | H66: " | I66: DJS
... A72: SKRU9908564 | C72: 40'RH | F72: -18 | G72: -18.3 | H72: " | I72: SKR
A76: < CY 보관지침 >
A77: 1. 최초 화주로 부터 지정된 온도(SETTING 온도를 말하며 수입목록 혹은 BAY PLAN에
A78: 표기된 온도)는 그 적정 온도를 유지하고 있는지 4시간마다 확인하여 기록 보관해야한다.
A79: 2. 온도를 지정하는 지시 및 표기가 없을 경우 일반적으로 채용되고 있는
A80: 냉동/냉장 화물의 운송온도를 기준으로 한다.
A81: 3. 만일 온도 이상 및 기타 기기의 이상이 발견될 시는 즉시 OPERATOR에게 통보하여야한다.
A86: CHIEF CHECKER | D86: STEVEDORE PCTC | H86: CHIEF OFFICER
A87: GREEN MARINE CO., LTD.
...

Sheet Performance
A1: GREEN MARINE CO., LTD
A2: PYEONGTAEK, KOREA
A4: PERFORMANCE REPORT
A6: M / V : | D6: DONGJIN CONTINENTAL | O6: VOY # : | R6: ='Final Work'!G4 -> 0220E & 0221W | Y6: DATE : | AB6: ='Final Work'!L4 -> 46222
A8: PIER : | D8: PCTC | O8: BERTH : | R8: ='Final Work'!G6 -> 6 | Y8: PORT : | AB8: PYEONGTAEK, KOREA
A10: Status | H10: FULL | P10: EMPTY | X10: TOTAL | AA10: REMARKS
A11: Description | H11: 20' | J11: 40' | L11: HC | N11: 45' | P11: 20' | R11: 40' | T11: HC | V11: 45'
A12: IN BOUND | X12: =SUM(H12:W12) -> 69 | AA12: RH x 2
X13: =SUM(H13:W13) -> 18
X14: =SUM(H14:W14) -> 5
X15: =SUM(H15:W15) -> 74 | AA15: 20'RF x 1 , RH x 6
X16: =SUM(H16:W16) -> 4
X17: =SUM(H17:W17) -> 0
X18: =SUM(H18:W18) -> 0
D19: S-TOTAL | H19: =SUM(H12:I18) -> 40 | J19: =SUM(J12:K18) -> 0 | L19: =SUM(L12:M18) -> 110 | N19: =SUM(N12:O18) -> 0 | P19: =SUM(P12:Q18) -> 20 | R19: =SUM(R12:S18) -> 0 | T19: =SUM(T12:U18) -> 0 | V19: =SUM(V12:W18) -> 0 | X19: =SUM(X12:Z18) -> 170
A20: OUT BOUND | X20: =SUM(H20:W20) -> 120 | AA20: RH x 8
X21: =SUM(H21:W21) -> 47 | AA21: 20'DG x 1
X22: =SUM(H22:W22) -> 5
X23: =SUM(H23:W23) -> 36 | AA23: 20'DG x 3 , RH x 10
X24: =SUM(H24:W24) -> 8 | AA24: 20'DG x 2
X25: =SUM(H25:W25) -> 0
X26: =SUM(H26:W26) -> 0
D27: S-TOTAL | H27: =SUM(H20:I26) -> 47 | J27: =SUM(J20:K26) -> 0 | L27: =SUM(L20:M26) -> 169 | N27: =SUM(N20:O26) -> 0 | P27: =SUM(P20:Q26) -> 0 | R27: =SUM(R20:S26) -> 0 | T27: =SUM(T20:U26) -> 0 | V27: =SUM(V20:W26) -> 0 | X27: =SUM(X20:Z26) -> 216
A28: SHIFT | D28: 1 TIME
D29: 1 TIME
A30: GRAND TOTAL | H30: =SUM(H19+H27+H28+H29) -> 87 | J30: =SUM(J19+J27+J28+J29) -> 0 | L30: =SUM(L19+L27+L28+L29) -> 279 | N30: =SUM(N19+N27+N28+N29) -> 0 | P30: =SUM(P19+P27+P28+P29) -> 20 | R30: =SUM(R19+R27+R28+R29) -> 0 | T30: =SUM(T19+T27+T28+T29) -> 0 | V30: =SUM(V19+V27+V28+V29) -> 0 | X30: =SUM(X19+X27+X28+X29) -> 386
A32: # WORKING PERIOD
A34: CRANE NO. | E34: FROM | K34: TO | Q34: HOURS | W34: REMARKS
A35: #3 (G/C) | E35: 0.35416667 | Q35: =IF(AND(NOT(ISBLANK(K35)),NOT(ISBLANK(E35))), IF(K35>E35,K35-E35,24-E35+K35), "") | W35: COMMENCED DISCH'
E36: =E35 -> 0.35416667 | K36: 0.47916667 | Q36: =IF(AND(NOT(ISBLANK(K36)),NOT(ISBLANK(E36))), IF(K36>E36,K36-E36,24-E36+K36), "") -> 0.125 | W36: DISCH' OF CONT'R
K37: 0.47916667 | Q37: =IF(AND(NOT(ISBLANK(K37)),NOT(ISBLANK(E37))), IF(K37>E37,K37-E37,24-E37+K37), "") | W37: COMPLETED DISCH'
E38: 0.48611111 | Q38: =IF(AND(NOT(ISBLANK(K38)),NOT(ISBLANK(E38))), IF(K38>E38,K38-E38,24-E38+K38), "") | W38: COMMENCED LOAD
E39: 0.48611111 | K39: 0.5 | Q39: =IF(AND(NOT(ISBLANK(K39)),NOT(ISBLANK(E39))), IF(K39>E39,K39-E39,24-E39+K39), "") -> 0.013888889 | W39: LOAD OF CONT'R
E40: 0.5 | K40: 0.54166667 | Q40: =IF(AND(NOT(ISBLANK(K40)),NOT(ISBLANK(E40))), IF(K40>E40,K40-E40,24-E40+K40), "") -> 0.041666667 | W40: MEAL TIME
E41: 0.54166667 | K41: 0.71527778 | Q41: =IF(AND(NOT(ISBLANK(K41)),NOT(ISBLANK(E41))), IF(K41>E41,K41-E41,24-E41+K41), "") -> 0.17361111 | W41: LOAD OF CONT'R
K42: 0.71527778 | Q42: =IF(AND(NOT(ISBLANK(K42)),NOT(ISBLANK(E42))), IF(K42>E42,K42-E42,24-E42+K42), "") | W42: COMPLETED LOAD & GANG K/OFF
Q43: =IF(AND(NOT(ISBLANK(K43)),NOT(ISBLANK(E43))), IF(K43>E43,K43-E43,24-E43+K43), "")
Q44: =IF(AND(NOT(ISBLANK(K44)),NOT(ISBLANK(E44))), IF(K44>E44,K44-E44,24-E44+K44), "")
Q45: =IF(AND(NOT(ISBLANK(K45)),NOT(ISBLANK(E45))), IF(K45>E45,K45-E45,24-E45+K45), "")
Q46: =IF(AND(NOT(ISBLANK(K46)),NOT(ISBLANK(E46))), IF(K46>E46,K46-E46,24-E46+K46), "")
...

Sheet SHIFTING
A1: GREEN MARINE CO., LTD.
A2: PYEONGTAEK, KOREA
A3: SHIFTING REPORT
A5: M.V. : DONGJIN CONTINENTAL | H5: VOY # : 0220E & 0221W
A6: DATE : 2026-07-19 | H6: PORT : PYEONGTAEK, KOREA
A8: NO | B8: CON'T NO | C8: TYPE | D8: F/E | E8: W/T | F8: OPR | G8: OLD | H8: NEW | I8: POD | J8: POL | K8: ACCOUNT
G9: POSN | H9: POSN
