Workbook

Sheet Final Work
A1: GREEN MARINE CO., LTD.
B2: FINAL WORKING REPORT (VOUCHER)
A4: M / V : | B4: SAWASDEE DENEB | F4: VOY # : | J4: DATE :
A6: PIER : | F6: BERTH : | J6: PORT : | L6: PYEONGTAEK, KOREA
A8: OPERATOR | B8: PORT | C8: FULL (F) | D8: =+"DISCH ("&D82+E82+F82+G82+D83+E83+F83+G83&")" -> DISCH (349) | H8: =+"LOAD ("&H82+I82+J82+K82+H83+I83+J83+K83&")" -> LOAD (284) | L8: =+"SHIFT ("&L82+M82+N82+O82+L83+M83+N83+O83&")" -> SHIFT (0)
C9: EMPTY(E) | D9: 20' | E9: 40' | F9: HC | G9: 45' | H9: 20' | I9: 40' | J9: HC | K9: 45' | L9: 20' | M9: 40' | N9: HC | O9: 45'
C10: F
C11: E
C12: F
C13: E
C14: F
C15: E
C16: F
C17: E
C18: F
C19: E
C20: F
C21: E
... C81: E
A82: Total | D82: =SUM(D10,D12,D14,D16,D18,D20,D22,D24,D26,D28,D30,D32,D34,D36,D38,D40,D42,D44,D46,D48,D50,D52,D54,D56,D58,D60,D62,D64,D66,D68,D70,D72,D74,D76,D78,D80) -> 79 | E82: =SUM(E10,E12,E14,E16,E18,E20,E22,E24,E26,E28,E30,E32,E34,E36,E38,E40,E42,E44,E46,E48,E50,E52,E54,E56,E58,E60,E62,E64,E66,E68,E70,E72,E74,E76,E78,E80) -> 0 | F82: =SUM(F10,F12,F14,F16,F18,F20,F22,F24,F26,F28,F30,F32,F34,F36,F38,F40,F42,F44,F46,F48,F50,F52,F54,F56,F58,F60,F62,F64,F66,F68,F70,F72,F74,F76,F78,F80) -> 261 | G82: =SUM(G10,G12,G14,G16,G18,G20,G22,G24,G26,G28,G30,G32,G34,G36,G38,G40,G42,G44,G46,G48,G50,G52,G54,G56,G58,G60,G62,G64,G66,G68,G70,G72,G74,G76,G78,G80) -> 0 | H82: =SUM(H10,H12,H14,H16,H18,H20,H22,H24,H26,H28,H30,H32,H34,H36,H38,H40,H42,H44,H46,H48,H50,H52,H54,H56,H58,H60,H62,H64,H66,H68,H70,H72,H74,H76,H78,H80) -> 133 | I82: =SUM(I10,I12,I14,I16,I18,I20,I22,I24,I26,I28,I30,I32,I34,I36,I38,I40,I42,I44,I46,I48,I50,I52,I54,I56,I58,I60,I62,I64,I66,I68,I70,I72,I74,I76,I78,I80) -> 0 | J82: =SUM(J10,J12,J14,J16,J18,J20,J22,J24,J26,J28,J30,J32,J34,J36,J38,J40,J42,J44,J46,J48,J50,J52,J54,J56,J58,J60,J62,J64,J66,J68,J70,J72,J74,J76,J78,J80) -> 69 | K82: =SUM(K10,K12,K14,K16,K18,K20,K22,K24,K26,K28,K30,K32,K34,K36,K38,K40,K42,K44,K46,K48,K50,K52,K54,K56,K58,K60,K62,K64,K66,K68,K70,K72,K74,K76,K78,K80) -> 0 | ... O82: =SUM(O10,O12,O14,O16,O18,O20,O22,O24,O26,O28,O30,O32,O34,O36,O38,O40,O42,O44,O46,O48,O50,O52,O54,O56,O58,O60,O62,O64,O66,O68,O70,O72,O74,O76,O78,O80) -> 0
D83: =SUM(D11,D13,D15,D17,D19,D21,D23,D25,D27,D29,D31,D33,D35,D37,D39,D41,D43,D45,D47,D49,D51,D53,D55,D57,D59,D61,D63,D65,D67,D69,D71,D73,D75,D77,D79,D81) -> 9 | E83: =SUM(E11,E13,E15,E17,E19,E21,E23,E25,E27,E29,E31,E33,E35,E37,E39,E41,E43,E45,E47,E49,E51,E53,E55,E57,E59,E61,E63,E65,E67,E69,E71,E73,E75,E77,E79,E81) -> 0 | F83: =SUM(F11,F13,F15,F17,F19,F21,F23,F25,F27,F29,F31,F33,F35,F37,F39,F41,F43,F45,F47,F49,F51,F53,F55,F57,F59,F61,F63,F65,F67,F69,F71,F73,F75,F77,F79,F81) -> 0 | G83: =SUM(G11,G13,G15,G17,G19,G21,G23,G25,G27,G29,G31,G33,G35,G37,G39,G41,G43,G45,G47,G49,G51,G53,G55,G57,G59,G61,G63,G65,G67,G69,G71,G73,G75,G77,G79,G81) -> 0 | H83: =SUM(H11,H13,H15,H17,H19,H21,H23,H25,H27,H29,H31,H33,H35,H37,H39,H41,H43,H45,H47,H49,H51,H53,H55,H57,H59,H61,H63,H65,H67,H69,H71,H73,H75,H77,H79,H81) -> 11 | I83: =SUM(I11,I13,I15,I17,I19,I21,I23,I25,I27,I29,I31,I33,I35,I37,I39,I41,I43,I45,I47,I49,I51,I53,I55,I57,I59,I61,I63,I65,I67,I69,I71,I73,I75,I77,I79,I81) -> 0 | J83: =SUM(J11,J13,J15,J17,J19,J21,J23,J25,J27,J29,J31,J33,J35,J37,J39,J41,J43,J45,J47,J49,J51,J53,J55,J57,J59,J61,J63,J65,J67,J69,J71,J73,J75,J77,J79,J81) -> 71 | K83: =SUM(K11,K13,K15,K17,K19,K21,K23,K25,K27,K29,K31,K33,K35,K37,K39,K41,K43,K45,K47,K49,K51,K53,K55,K57,K59,K61,K63,K65,K67,K69,K71,K73,K75,K77,K79,K81) -> 0 | ... O83: =SUM(O11,O13,O15,O17,O19,O21,O23,O25,O27,O29,O31,O33,O35,O37,O39,O41,O43,O45,O47,O49,O51,O53,O55,O57,O59,O61,O63,O65,O67,O69,O71,O73,O75,O77,O79,O81) -> 0
A85: Remarks : Discharging | H85: Remarks : Loading
A100: CHIEF CHECKER | J100: CHIEF OFFICER

Sheet Time sheet
A1: GREEN MARINE CO., LTD.
A2: PYEONGTAEK, KOREA
C3: T I M E S H E E T
A5: M / V: | B5: SAWASDEE DENEB | C5: VOY # : 2607N & 2608S | G5: DATE : | H5: ='Final Work'!L4 -> 46218
A7: PIER : | B7: PCTC | D7: BERTH : | E7: ='Final Work'!G6 -> 6 | G7: WEATHER : | H7: Rainy
H9: PORT : PYEONGTAEK, KOREA
A11: T I M E | C11: R E M A R K S
A12: 14th
A15: 15th
A41: CHIEF CHECKER

Sheet OS-IN
A1: GREEN MARINE CO., LTD.
A2: PYEONGTAEK, KOREA
A4: CARGO OVERAGE & SHORTAGE REPORT (DISCH)
A6: M / V : | B6: ='Final Work'!B4 -> SAWASDEE DENEB | G6: VOY. NO.: | K6: DATE :
A8: PORT : | B8: PYEONGTAEK, KOREA | G8: PIER : | K8: BERTH :
A10: B/L NO. | B10: MARKS (PORT) | D10: DESCRIPTION | G10: TYPE OF | H10: MANIFESTED | J10: DISCHARGED | K10: OVER | L10: SHORT | M10: REMARKS
G11: PKGS
D23: T O T A L | G23: VAN | H23: =SUM(H13:I22) -> 349 | J23: =SUM(J12:J22) -> 349 | K23: NIL | L23: NIL
A26: REMARKS
A38: CHIEF CHECKER | G38: STEVEDORE PCTC | L38: CHIEF OFFICER

Sheet DM-IN
A1: GREEN MARINE CO., LTD.
A2: PYEONGTAEK, KOREA
A4: CARGO DAMAGE REPORT
A6: M / V : | B6: ='OS-IN'!B6 -> SAWASDEE DENEB | I6: VOY. NO. : 2607N | O6: DATE : | P6: ='OS-IN'!L6 -> 46218
A8: PORT : | B8: PYEONGTAEK, KOREA | I8: PIER : PCTC | O8: BERTH : | P8: ='Final Work'!G6 -> 6
A10: PORT | B10: B/L NO. | C10: MARKS | F10: CONTENTS | J10: NO. OF | K10: TYPE | L10: EXCEPTION ( Found in stow )
J11: PKGS
A34: CHIEF CHECKER | I34: STEVEDORE PCTC | O34: CHIEF OFFICER

Sheet OS-OUT
A1: GREEN MARINE CO., LTD.
A2: PYEONGTAEK, KOREA
A4: CARGO OVERAGE & SHORTAGE REPORT (LOAD)
A6: M / V : | B6: ='Final Work'!B4 -> SAWASDEE DENEB | G6: VOY. NO.: | K6: DATE :
A8: PORT : | B8: PYEONGTAEK, KOREA | G8: PIER : | K8: BERTH :
A10: B/L NO. | B10: MARKS (PORT) | D10: DESCRIPTION | G10: TYPE OF | H10: MANIFESTED | J10: LOADED | K10: OVER | L10: SHORT | M10: REMARKS
G11: PKGS
D25: T O T A L | G25: VAN | H25: =SUM(H12:I24) -> 284 | J25: =SUM(J12:J24) -> 284 | K25: NIL | L25: NIL
A27: REMARKS
A37: CHIEF CHECKER | G37: STEVEDORE PCTC | L37: CHIEF OFFICER

Sheet DM-OUT 
A1: GREEN MARINE CO., LTD.
A2: PYEONGTAEK, KOREA
A4: CARGO DAMAGE REPORT
A6: M / V : | B6: ='OS-OUT'!B6 -> SAWASDEE DENEB | I6: VOY. NO. : 2608S | O6: DATE : | P6: ='OS-OUT'!L6 -> 46218
A8: PORT : | B8: PYEONGTAEK, KOREA | I8: PIER : PCTC | O8: BERTH : | P8: ='OS-OUT'!L8 -> 6
A10: PORT | B10: B/L NO. | C10: MARKS | F10: CONTENTS | J10: NO. OF | K10: TYPE | L10: EXCEPTION ( Prior To Load )
J11: PKGS
A33: CHIEF CHECKER | I33: STEVEDORE PCTC | O33: CHIEF OFFICER

Sheet Act. Cntr-Seal No List
A1: GREEN MARINE CO., LTD.
A2: PYEONGTAEK, KOREA
A4: M / V : SAWASDEE DENEB | F4: DATE :
A6: VOY.NO.: 2607N | F6: PORT : | G6: PYEONGTAEK, KOREA
C8: ACTUAL CONTAINER & SEAL NUMBER LIST
H9: DISCH.
A10: MANIFEST | D10: SIZE | E10: ACTUAL | G10: RESEAL NO. | H10: REMARKS
A11: CONT'R NO. | C11: SEAL NO. | E11: CONT'R NO. | F11: SEAL NO.
A33: 20FT | B33: FULL | C33: 1
B34: EMPTY
A35: 40FT | B35: FULL
B36: EMPTY
A37: TOTAL | C37: =SUM(C33:C36) -> 1 | G37: CHIEF CHECKER
A38: GREEN MARINE CO., LTD.
A39: PYEONGTAEK, KOREA
A41: =A4 -> M / V : SAWASDEE DENEB | F41: DATE : | G41: ='OS-OUT'!L6 -> 46218
A43: VOY.NO.: 2608S | F43: PORT : | G43: PYEONGTAEK, KOREA
C45: ACTUAL CONTAINER & SEAL NUMBER LIST
H46: LOAD.
A47: MANIFEST | D47: SIZE | E47: ACTUAL | G47: RESEAL NO. | H47: REMARKS
A48: CONT'R NO. | C48: SEAL NO. | E48: CONT'R NO. | F48: SEAL NO.
A49: HLHU8521486 | C49: HAL08550 | D49: 40' | F49: HAL085550 | H49: SGN - HAS
A70: 20FT | B70: FULL
B71: EMPTY
A72: 40FT | B72: FULL | C72: 1
B73: EMPTY
A74: TOTAL | C74: =SUM(C70:C73) -> 1 | G74: CHIEF CHECKER

Sheet RF condition report
A1: GREEN MARINE CO., LTD.
A2: PYEONGTAEK, KOREA
A4: REEFER CONTAINER CONDITION REPORT
A5: Discharging / Loading
I6: ( 1/1 )
A7: ='Act. Cntr-Seal No List'!A4:D4 -> M / V : SAWASDEE DENEB | D7: VOY # : | E7: ='OS-IN'!H6 -> 2607N | G7: DATE : | H7: 46217
A8: PIER : PCTC | D8: BERTH : | E8: ='OS-IN'!L8 -> 6 | G8: PORT : | H8: PYEONGTAEK, KOREA
A10: CONTAINER NO. | B10: SEAL NO. | C10: SIZE | D10: LOCATION | F10: TEMPERATURE | H10: TIME | I10: REMARKS
D11: Bay/Slot/Tier | F11: Setting | G11: Actual | H11: Plug In / Out
A42: CHIEF CHECKER | D42: STEVEDORE PCTC | H42: CHIEF OFFICER
A43: GREEN MARINE CO., LTD.
A44: PYEONGTAEK, KOREA
A46: REEFER CONTAINER CONDITION REPORT
A47: Discharging / Loading
I48: (2/2 )
A49: =A7 -> M / V : SAWASDEE DENEB | D49: VOY # : | E49: =E7 -> 2607N | G49: DATE : | H49: =H7 -> 46217
A50: PIER : PCTC | D50: BERTH : | E50: =E8 -> 6 | G50: PORT : | H50: PYEONGTAEK, KOREA
A52: CONTAINER NO. | B52: SEAL NO. | C52: SIZE | D52: LOCATION | F52: TEMPERATURE | H52: TIME | I52: REMARKS
D53: Bay/Slot/Tier | F53: Setting | G53: Actual | H53: Plug In / Out
A54: SKRU9903109 | C54: 40'RH | F54: 14 | G54: 14 | H54: =H12 -> NaN | I54: SKR-SGN
A75: < CY 보관지침 >
A76: 1. 최초 화주로 부터 지정된 온도(SETTING 온도를 말하며 수입목록 혹은 BAY PLAN에
A77: 표기된 온도)는 그 적정 온도를 유지하고 있는지 4시간마다 확인하여 기록 보관해야한다.
A78: 2. 온도를 지정하는 지시 및 표기가 없을 경우 일반적으로 채용되고 있는
A79: 냉동/냉장 화물의 운송온도를 기준으로 한다.
A80: 3. 만일 온도 이상 및 기타 기기의 이상이 발견될 시는 즉시 OPERATOR에게 통보하여야한다.
A84: CHIEF CHECKER | D84: STEVEDORE PCTC | H84: CHIEF OFFICER
A85: GREEN MARINE CO., LTD.
A86: PYEONGTAEK, KOREA
A88: REEFER CONTAINER CONDITION REPORT
A89: Discharging / Loading
I90: ( 1/1 )
A91: =A7 -> M / V : SAWASDEE DENEB | D91: VOY # : | E91: ='OS-OUT'!H6 -> 2608S | G91: DATE : | H91: ='OS-OUT'!L6 -> 46218
A92: PIER : PCTC | D92: BERTH : | E92: =E8 -> 6 | G92: PORT : | H92: PYEONGTAEK, KOREA
A94: CONTAINER NO. | B94: SEAL NO. | C94: SIZE | D94: LOCATION | F94: TEMPERATURE | H94: TIME | I94: REMARKS
D95: Bay/Slot/Tier | F95: Setting | G95: Actual | H95: Plug In / Out
A96: FBIU5373094 | C96: 40'RH | F96: -25 | G96: -23.4 | H96: 14:50HR'S | I96: SKR-PUS
A97: FSCU5895715 | C97: 40'RH | F97: -25 | G97: -24.9 | H97: " | I97: SKR-PUS
A98: FSCU5897220 | C98: 40'RH | F98: -25 | G98: -23.1 | H98: " | I98: SKR-PUS
A99: SKRU9908857 | C99: 40'RH | F99: -25 | G99: -23.9 | H99: " | I99: SKR-PUS
...

Sheet Performance
A1: GREEN MARINE CO., LTD
A2: PYEONGTAEK, KOREA
A4: PERFORMANCE REPORT
A6: M/V : | D6: ='Final Work'!B4 -> SAWASDEE DENEB | O6: VOY # : | R6: ='Final Work'!G4 -> 2607N & 2608S | Y6: DATE : | AB6: ='Final Work'!L4 -> 46218
A8: PIER : | D8: PCTC | O8: BERTH : | R8: ='Final Work'!G6 -> 6 | Y8: PORT : | AB8: PYEONGTAEK, KOREA
A10: Status | H10: FULL | P10: EMPTY | X10: TOTAL | AA10: REMARKS
A11: Description | H11: 20' | J11: 40' | L11: HC | N11: 45' | P11: 20' | R11: 40' | T11: HC | V11: 45'
A12: IN BOUND | X12: =SUM(H12:W12) -> 109 | AA12: 40'RH x 3
X13: =SUM(H13:W13) -> 91 | AA13: 20'RF x 1 , 40'RH x 1
X14: =SUM(H14:W14) -> 107
X15: =SUM(H15:W15) -> 42 | AA15: 40'RH x 4
X16: =SUM(H16:W16) -> 0
X17: =SUM(H17:W17) -> 0
D18: S-TOTAL | H18: =SUM(H12:I17) -> 79 | J18: =SUM(J12:K17) -> 0 | L18: =SUM(L12:M17) -> 261 | N18: =SUM(N12:O17) -> 0 | P18: =SUM(P12:Q17) -> 9 | R18: =SUM(R12:S17) -> 0 | T18: =SUM(T12:U17) -> 0 | V18: =SUM(V12:W17) -> 0 | X18: =SUM(H18:W18) -> 349
A19: OUT BOUND | X19: =SUM(H19:W19) -> 32 | AA19: 40'DG x 1 , 40'RH x 6
X20: =SUM(H20:W20) -> 122 | AA20: 40'RH x 8
X21: =SUM(H21:W21) -> 120 | AA21: 20'DG x 9
X22: =SUM(H22:W22) -> 9 | AA22: 20'DG x 7
X23: =SUM(H23:W23) -> 1
X24: =SUM(H24:W24) -> 0
X25: =SUM(H25:W25) -> 0
D26: S-TOTAL | H26: =SUM(H19:I25) -> 133 | J26: =SUM(J19:K25) -> 0 | L26: =SUM(L19:M25) -> 69 | N26: =SUM(N19:O25) -> 0 | P26: =SUM(P19:Q25) -> 11 | R26: =SUM(R19:S25) -> 0 | T26: =SUM(T19:U25) -> 71 | V26: =SUM(V19:W25) -> 0 | X26: =SUM(X19:Z25) -> 284
A27: SHIFT | D27: 1 TIME
D28: 1 TIME
A29: GRAND TOTAL | H29: =SUM(H18+H26+H27+H28) -> 212 | J29: =SUM(J18+J26+J27+J28) -> 0 | L29: =SUM(L18+L26+L27+L28) -> 330 | N29: =SUM(N18+N26+N27+N28) -> 0 | P29: =SUM(P18+P26+P27+P28) -> 20 | R29: =SUM(R18+R26+R27+R28) -> 0 | T29: =SUM(T18+T26+T27+T28) -> 71 | V29: =SUM(V18+V26+V27+V28) -> 0 | X29: =SUM(X18+X26+X27+X28) -> 633
A31: # WORKING PERIOD
A33: CRANE NO. | E33: FROM | K33: TO | Q33: HOURS | W33: REMARKS
A34: #2 (G/C) | E34: 0.46180556 | Q34: =IF(AND(NOT(ISBLANK(K34)),NOT(ISBLANK(E34))), IF(K34>E34,K34-E34,24-E34+K34), "") | W34: COMMENCED LOAD.
A35: 15th | E35: =E34 -> 0.46180556 | K35: 0.5 | Q35: =IF(AND(NOT(ISBLANK(K35)),NOT(ISBLANK(E35))), IF(K35>E35,K35-E35,24-E35+K35), "") -> 0.038194444 | W35: LOAD. OF CONT'R
E36: =K35 -> 0.5 | K36: 0.54166667 | Q36: =IF(AND(NOT(ISBLANK(K36)),NOT(ISBLANK(E36))), IF(K36>E36,K36-E36,24-E36+K36), "") -> 0.041666667 | W36: MEAL TIME
E37: =K36 -> 0.54166667 | K37: 0.59027778 | Q37: =IF(AND(NOT(ISBLANK(K37)),NOT(ISBLANK(E37))), IF(K37>E37,K37-E37,24-E37+K37), "") -> 0.048611111 | W37: LOAD. OF CONT'R
K38: =K37 -> 0.59027778 | Q38: =IF(AND(NOT(ISBLANK(K38)),NOT(ISBLANK(E38))), IF(K38>E38,K38-E38,24-E38+K38), "") | W38: COMPLETED LOAD. & GANGS K/OFF
Q39: =IF(AND(NOT(ISBLANK(K39)),NOT(ISBLANK(E39))), IF(K39>E39,K39-E39,24-E39+K39), "")
Q40: =IF(AND(NOT(ISBLANK(K40)),NOT(ISBLANK(E40))), IF(K40>E40,K40-E40,24-E40+K40), "")
Q41: =IF(AND(NOT(ISBLANK(K41)),NOT(ISBLANK(E41))), IF(K41>E41,K41-E41,24-E41+K41), "")
Q42: =IF(AND(NOT(ISBLANK(K42)),NOT(ISBLANK(E42))), IF(K42>E42,K42-E42,24-E42+K42), "")
Q43: =IF(AND(NOT(ISBLANK(K43)),NOT(ISBLANK(E43))), IF(K43>E43,K43-E43,24-E43+K43), "")
Q44: =IF(AND(NOT(ISBLANK(K44)),NOT(ISBLANK(E44))), IF(K44>E44,K44-E44,24-E44+K44), "")
Q45: =IF(AND(NOT(ISBLANK(K45)),NOT(ISBLANK(E45))), IF(K45>E45,K45-E45,24-E45+K45), "")
Q46: =IF(AND(NOT(ISBLANK(K46)),NOT(ISBLANK(E46))), IF(K46>E46,K46-E46,24-E46+K46), "")
...
