Workbook

Sheet Final Work
A1: GREEN MARINE CO., LTD.
B2: FINAL WORKING REPORT (VOUCHER)
A4: M/V : | B4: DONGJIN CONFIDENT | F4: VOY # : | J4: DATE :
A6: PIER : | F6: BERTH : | J6: PORT : | L6: PYEONGTAEK, KOREA
A8: OPERATOR | B8: PORT | C8: FULL (F) | D8: =+"DISCH ("&D82+E82+F82+G82+D83+E83+F83+G83&")" -> DISCH (256) | H8: =+"LOAD ("&H82+I82+J82+K82+H83+I83+J83+K83&")" -> LOAD (241) | L8: =+"SHIFT ("&L82+M82+N82+O82+L83+M83+N83+O83&")" -> SHIFT (0)
C9: EMPTY(E) | D9: 20' | E9: 40' | F9: HC | G9: 45' | H9: 20' | I9: 40' | J9: HC | K9: 45' | L9: 20' | M9: 40' | N9: HC | O9: 45'
C10: F
C11: E
C12: F
C13: E
C14: F
C15: E
C16: F
C17: E
C18: F
C19: E
C20: F
C21: E
... C81: E
A82: Total | D82: =SUM(D10,D12,D14,D16,D18,D20,D22,D24,D26,D28,D30,D32,D34,D36,D38,D40,D42,D44,D46,D48,D50,D52,D54,D56,D58,D60,D62,D64,D66,D68,D70,D72,D74,D76,D78,D80) -> 93 | E82: =SUM(E10,E12,E14,E16,E18,E20,E22,E24,E26,E28,E30,E32,E34,E36,E38,E40,E42,E44,E46,E48,E50,E52,E54,E56,E58,E60,E62,E64,E66,E68,E70,E72,E74,E76,E78,E80) -> 0 | F82: =SUM(F10,F12,F14,F16,F18,F20,F22,F24,F26,F28,F30,F32,F34,F36,F38,F40,F42,F44,F46,F48,F50,F52,F54,F56,F58,F60,F62,F64,F66,F68,F70,F72,F74,F76,F78,F80) -> 163 | G82: =SUM(G10,G12,G14,G16,G18,G20,G22,G24,G26,G28,G30,G32,G34,G36,G38,G40,G42,G44,G46,G48,G50,G52,G54,G56,G58,G60,G62,G64,G66,G68,G70,G72,G74,G76,G78,G80) -> 0 | H82: =SUM(H10,H12,H14,H16,H18,H20,H22,H24,H26,H28,H30,H32,H34,H36,H38,H40,H42,H44,H46,H48,H50,H52,H54,H56,H58,H60,H62,H64,H66,H68,H70,H72,H74,H76,H78,H80) -> 91 | I82: =SUM(I10,I12,I14,I16,I18,I20,I22,I24,I26,I28,I30,I32,I34,I36,I38,I40,I42,I44,I46,I48,I50,I52,I54,I56,I58,I60,I62,I64,I66,I68,I70,I72,I74,I76,I78,I80) -> 0 | J82: =SUM(J10,J12,J14,J16,J18,J20,J22,J24,J26,J28,J30,J32,J34,J36,J38,J40,J42,J44,J46,J48,J50,J52,J54,J56,J58,J60,J62,J64,J66,J68,J70,J72,J74,J76,J78,J80) -> 39 | K82: =SUM(K10,K12,K14,K16,K18,K20,K22,K24,K26,K28,K30,K32,K34,K36,K38,K40,K42,K44,K46,K48,K50,K52,K54,K56,K58,K60,K62,K64,K66,K68,K70,K72,K74,K76,K78,K80) -> 0 | ... O82: =SUM(O10,O12,O14,O16,O18,O20,O22,O24,O26,O28,O30,O32,O34,O36,O38,O40,O42,O44,O46,O48,O50,O52,O54,O56,O58,O60,O62,O64,O66,O68,O70,O72,O74,O76,O78,O80) -> 0
D83: =SUM(D11,D13,D15,D17,D19,D21,D23,D25,D27,D29,D31,D33,D35,D37,D39,D41,D43,D45,D47,D49,D51,D53,D55,D57,D59,D61,D63,D65,D67,D69,D71,D73,D75,D77,D79,D81) -> 0 | E83: =SUM(E11,E13,E15,E17,E19,E21,E23,E25,E27,E29,E31,E33,E35,E37,E39,E41,E43,E45,E47,E49,E51,E53,E55,E57,E59,E61,E63,E65,E67,E69,E71,E73,E75,E77,E79,E81) -> 0 | F83: =SUM(F11,F13,F15,F17,F19,F21,F23,F25,F27,F29,F31,F33,F35,F37,F39,F41,F43,F45,F47,F49,F51,F53,F55,F57,F59,F61,F63,F65,F67,F69,F71,F73,F75,F77,F79,F81) -> 0 | G83: =SUM(G11,G13,G15,G17,G19,G21,G23,G25,G27,G29,G31,G33,G35,G37,G39,G41,G43,G45,G47,G49,G51,G53,G55,G57,G59,G61,G63,G65,G67,G69,G71,G73,G75,G77,G79,G81) -> 0 | H83: =SUM(H11,H13,H15,H17,H19,H21,H23,H25,H27,H29,H31,H33,H35,H37,H39,H41,H43,H45,H47,H49,H51,H53,H55,H57,H59,H61,H63,H65,H67,H69,H71,H73,H75,H77,H79,H81) -> 1 | I83: =SUM(I11,I13,I15,I17,I19,I21,I23,I25,I27,I29,I31,I33,I35,I37,I39,I41,I43,I45,I47,I49,I51,I53,I55,I57,I59,I61,I63,I65,I67,I69,I71,I73,I75,I77,I79,I81) -> 0 | J83: =SUM(J11,J13,J15,J17,J19,J21,J23,J25,J27,J29,J31,J33,J35,J37,J39,J41,J43,J45,J47,J49,J51,J53,J55,J57,J59,J61,J63,J65,J67,J69,J71,J73,J75,J77,J79,J81) -> 110 | K83: =SUM(K11,K13,K15,K17,K19,K21,K23,K25,K27,K29,K31,K33,K35,K37,K39,K41,K43,K45,K47,K49,K51,K53,K55,K57,K59,K61,K63,K65,K67,K69,K71,K73,K75,K77,K79,K81) -> 0 | ... O83: =SUM(O11,O13,O15,O17,O19,O21,O23,O25,O27,O29,O31,O33,O35,O37,O39,O41,O43,O45,O47,O49,O51,O53,O55,O57,O59,O61,O63,O65,O67,O69,O71,O73,O75,O77,O79,O81) -> 0
A85: Remarks : Discharging | H85: Remarks : Loading
A94: CHIEF CHECKER | J94: CHIEF OFFICER

Sheet Time sheet
A1: GREEN MARINE CO., LTD.
A2: PYEONGTAEK, KOREA
C3: T I M E S H E E T
A5: M/V : | B5: DONGJIN CONFIDENT | D5: VOY # : 0148N & 0149S | G5: DATE : 2026-07-20
A7: PIER: | B7: PCTC | D7: BERTH : | E7: ='Final Work'!G6 -> 6 | G7: WEATHER : | H7: RAIN
H9: PORT : PYEONGTAEK, KOREA
A11: T I M E | C11: R E M A R K S
A12: 20th
A46: CHIEF CHECKER

Sheet OS-IN
A1: GREEN MARINE CO., LTD.
A2: PYEONGTAEK, KOREA
A4: CARGO OVERAGE & SHORTAGE REPORT (DISCH)
A6: M / V : | B6: DONGJIN CONFIDENT | G6: VOY. NO.: | K6: DATE :
A8: PORT : | B8: PYEONGTAEK, KOREA | G8: PIER : | K8: BERTH :
A10: B/L NO. | B10: MARKS (PORT) | D10: DESCRIPTION | G10: TYPE OF | H10: MANIFESTED | J10: DISCHARGED | K10: OVER | L10: SHORT | M10: REMARKS
G11: PKGS
D20: T O T A L | G20: VAN | H20: =SUM(H12:I19) -> 256 | J20: =SUM(J12:J19) -> 256 | K20: NIL | L20: NIL
A24: REMARKS
A34: CHIEF CHECKER | G34: STEVEDORE PCTC | L34: CHIEF OFFICER

Sheet DM-IN
A1: GREEN MARINE CO., LTD.
A2: PYEONGTAEK, KOREA
A4: CARGO DAMAGE REPORT
A6: M / V : | B6: DONGJIN CONFIDENT | I6: VOY. NO. : | K6: ='OS-IN'!H6 -> 0148N | O6: DATE : | P6: ='OS-IN'!L6 -> 46223
A8: PORT : | B8: PYEONGTAEK, KOREA | I8: PIER : PCTC | O8: BERTH: | P8: ='Final Work'!G6 -> 6
A10: PORT | B10: B/L NO. | C10: MARKS | F10: CONTENTS | J10: NO. OF | K10: TYPE | L10: EXCEPTION ( Found in stow )
J11: PKGS
A32: CHIEF CHECKER | I32: STEVEDORE PCTC | O32: CHIEF OFFICER

Sheet OS-OUT
A1: GREEN MARINE CO., LTD.
A2: PYEONGTAEK, KOREA
A4: CARGO OVERAGE & SHORTAGE REPORT (LOAD)
A6: M / V : | B6: DONGJIN CONFIDENT | G6: VOY. NO.: | K6: DATE :
A8: PORT : | B8: PYEONGTAEK, KOREA | G8: PIER : | K8: BERTH :
A10: B/L NO. | B10: MARKS (PORT) | D10: DESCRIPTION | G10: TYPE OF | H10: MANIFESTED | J10: LOADED | K10: OVER | L10: SHORT | M10: REMARKS
G11: PKGS
D25: T O T A L | G25: VAN | H25: =SUM(H12:I24) -> 241 | J25: =SUM(J12:J24) -> 241 | K25: NIL | L25: NIL
A29: REMARKS
A39: CHIEF CHECKER | G39: STEVEDORE PCTC | L39: CHIEF OFFICER

Sheet DM-OUT 
A1: GREEN MARINE CO., LTD.
A2: PYEONGTAEK, KOREA
A4: CARGO DAMAGE REPORT
A6: M / V : | B6: DONGJIN CONFIDENT | I6: VOY. NO. : | K6: ='OS-OUT'!H6 -> 0149S | O6: DATE : | P6: ='OS-OUT'!L6 -> 46223
A8: PORT : | B8: PYEONGTAEK, KOREA | I8: PIER : PCTC | O8: BERTH: | P8: ='Final Work'!G6 -> 6
A10: PORT | B10: B/L NO. | C10: MARKS | F10: CONTENTS | J10: NO. OF | K10: TYPE | L10: EXCEPTION ( Prior To Load )
J11: PKGS
A32: CHIEF CHECKER | I32: STEVEDORE PCTC | O32: CHIEF OFFICER

Sheet DAMAGE-EACH
A1: GREEN MARINE CO., LTD.
A2: PYEONGTAEK, KOREA
A4: CONTAINER DAMAGED REPORT
A6: M / V : | B6: DONGJIN CONFIDENT | F6: VOY. NO. : | H6: ='OS-IN'!H6:I6 -> 0148N | J6: DATE : | K6: ='OS-IN'!L6 -> 46223
A8: CONTAINER NO : | F8: SEAL NO. : | J8: SIZE : | K8: 20' | L8: 40' | M8: 45'
A9: OPERATOR :
M10: PORT : PYEONGTAEK, KOREA
A33: Description of Damage :
B34: ( Found in stow )
B35: -NIL-
A40: SYMBOLS
A41: B | B41: BO | C41: BU | D41: C | E41: D | F41: DO | G41: H | H41: M | I41: O | J41: P | K41: R | L41: S | M41: T
A42: Broken | B42: Bulged out | C42: Buckled | D42: Cut | E42: Dent | F42: Distorted | G42: Hole | H42: Miss | I42: Burned out | J42: Patch | K42: Rusty | L42: Scratch | M42: Torn
A49: CHIEF CHECKER | F49: STEVEDORE | K49: CHIEF OFFICER

Sheet Act. Cntr-Seal No List
A1: GREEN MARINE CO., LTD.
A2: PYEONGTAEK, KOREA
A4: M / V : DONGJIN CONFIDENT | F4: DATE :
A6: VOY.NO. : | C6: ='OS-IN'!H6 -> 0148N | F6: PORT : | G6: PYEONGTAEK, KOREA
C8: ACTUAL CONTAINER & SEAL NUMBER LIST
H9: DISCH.
A10: MANIFEST | D10: SIZE | E10: ACTUAL | G10: RESEAL NO. | H10: REMARKS
A11: CONT'R NO. | C11: SEAL NO. | E11: CONT'R NO. | F11: SEAL NO.
A33: 20FT | B33: EMPTY
B34: FULL
A35: 40FT | B35: EMPTY
B36: FULL
A37: TOTAL | C37: =SUM(C33:C36) -> 0 | G37: CHIEF CHECKER
A38: GREEN MARINE CO., LTD.
A39: PYEONGTAEK, KOREA
A41: M / V : DONGJIN CONFIDENT | F41: DATE : | G41: ='OS-OUT'!L6 -> 46223
A43: VOY.NO. : | C43: ='OS-OUT'!H6 -> 0149S | F43: PORT : | G43: PYEONGTAEK, KOREA
C45: ACTUAL CONTAINER & SEAL NUMBER LIST
H46: LOAD.
A47: MANIFEST | D47: SIZE | E47: ACTUAL | G47: RESEAL NO. | H47: REMARKS
A48: CONT'R NO. | C48: SEAL NO. | E48: CONT'R NO. | F48: SEAL NO.
A49: -NIL-
A70: 20FT | B70: EMPTY
B71: FULL
A72: 40FT | B72: EMPTY
B73: FULL
A74: TOTAL | C74: =SUM(C70:C73) -> 0 | G74: CHIEF CHECKER

Sheet RF condition report
A1: GREEN MARINE CO., LTD.
A2: PYEONGTAEK, KOREA
A4: REEFER CONTAINER CONDITION REPORT
A5: Disharging / Loading
I6: ( 1/1 )
A7: M/V : DONGJIN CONFIDENT | D7: VOY # : | E7: ='OS-IN'!H6 -> 0148N | G7: DATE : | H7: ='OS-IN'!L6 -> 46223
A8: PIER : PCTC | D8: BERTH : | E8: ='Final Work'!G6 -> 6 | G8: PORT : | H8: PYEONGTAEK, KOREA
A10: ONTAINER NO. | B10: SEAL NO. | C10: SIZE | D10: LOATION | F10: TEMPERATURE | H10: TIME | I10: REMARKS
D11: Bay/Slot/Tier | F11: Setting | G11: Atual | H11: Plug In / Out
A48: CHIEF HEKER | D48: STEVEDORE PCTC | H48: CHIEF OFFIER
A49: GREEN MARINE CO., LTD.
A50: PYEONGTAEK, KOREA
A52: REEFER CONTAINER CONDITION REPORT
A53: Disharging / Loading
I54: ( 2/2 )
A55: M/V : DONGJIN CONFIDENT | D55: VOY # : | E55: =E7 -> 0148N | G55: DATE : | H55: =H7 -> 46223
A56: PIER : PCTC | D56: BERTH : | E56: 7 | G56: PORT : | H56: PYEONGTAEK, KOREA
A58: ONTAINER NO. | B58: SEAL NO. | C58: SIZE | D58: LOATION | F58: TEMPERATURE | H58: TIME | I58: REMARKS
D59: Bay/Slot/Tier | F59: Setting | G59: Atual | H59: Plug In / Out
A81: < Y 보관지침 >
A82: 1. 최초 화주로 부터 지정된 온도(SETTING 온도를 말하며 수입목록 혹은 BAY PLAN에
A83: 표기된 온도)는 그 적정 온도를 유지하고 있는지 4시간마다 확인하여 기록 보관해야한다.
A84: 2. 온도를 지정하는 지시 및 표기가 없을 경우 일반적으로 채용되고 있는
A85: 냉동/냉장 화물의 운송온도를 기준으로 한다.
A86: 3. 만일 온도 이상 및 기타 기기의 이상이 발견될 시는 즉시 OPERATOR에게 통보하여야한다.
A91: CHIEF HEKER | D91: STEVEDORE PCTC | H91: CHIEF OFFIER
A92: GREEN MARINE CO., LTD.
A93: PYEONGTAEK, KOREA
A95: REEFER CONTAINER CONDITION REPORT
A96: Disharging / Loading
I97: ( 1/1 )
A98: M/V : DONGJIN CONFIDENT | D98: VOY # : | E98: ='OS-OUT'!H6 -> 0149S | G98: DATE : | H98: ='OS-OUT'!L6 -> 46223
A99: PIER : PCTC | D99: BERTH : | E99: ='Final Work'!G6 -> 6 | G99: PORT : | H99: PYEONGTAEK, KOREA
A101: ONTAINER NO. | B101: SEAL NO. | C101: SIZE | D101: LOATION | F101: TEMPERATURE | H101: TIME | I101: REMARKS
D102: Bay/Slot/Tier | F102: Setting | G102: Atual | H102: Plug In / Out
A103: OTPU6568405 | C103: 40'RH | F103: -18 | G103: -11.4 | H103: 10:00HRS | I103: SGN - DJS
A124: < Y 보관지침 >
A125: 1. 최초 화주로 부터 지정된 온도(SETTING 온도를 말하며 수입목록 혹은 BAY PLAN에
A126: 표기된 온도)는 그 적정 온도를 유지하고 있는지 4시간마다 확인하여 기록 보관해야한다.
A127: 2. 온도를 지정하는 지시 및 표기가 없을 경우 일반적으로 채용되고 있는
...

Sheet Performance
A1: GREEN MARINE CO., LTD
A2: PYEONGTAEK, KOREA
A4: PERFORMANCE REPORT
A6: M/V : | D6: DONGJIN CONFIDENT | O6: VOY # : | R6: ='Final Work'!G4 -> 0148N & 0149S | Y6: DATE : | AB6: ='Final Work'!L4 -> 46223
A8: PIER : | D8: PCTC | O8: BERTH : | R8: ='Final Work'!G6 -> 6 | Y8: PORT : | AB8: PYEONGTAEK, KOREA
A10: Status | H10: FULL | P10: EMPTY | X10: TOTAL | AA10: REMARKS
A11: Description | H11: 20' | J11: 40' | L11: HC | N11: 45' | P11: 20' | R11: 40' | T11: HC | V11: 45'
A12: IN BOUND | X12: =SUM(H12:W12) -> 51 | AA12: RH x 8
X13: =SUM(H13:W13) -> 68 | AA13: RH x 1
X14: =SUM(H14:W14) -> 96 | AA14: 20'RF x 1 , RH x 6
X15: =SUM(H15:W15) -> 41 | AA15: RH x 6
X16: =SUM(H16:W16) -> 0
X17: =SUM(H17:W17) -> 0
D18: S-TOTAL | H18: =SUM(H12:I17) -> 93 | J18: =SUM(J12:K17) -> 0 | L18: =SUM(L12:M17) -> 163 | N18: =SUM(N12:O17) -> 0 | P18: =SUM(P12:Q17) -> 0 | R18: =SUM(R12:S17) -> 0 | T18: =SUM(T12:U17) -> 0 | V18: =SUM(V12:W17) -> 0 | X18: =SUM(H18:W18) -> 256
A19: OUT BOUND | X19: =SUM(H19:W19) -> 60 | AA19: 20'DG x 6 ( TK x 4 )
X20: =SUM(H20:W20) -> 110
X21: =SUM(H21:W21) -> 32 | AA21: 20'DG x 8 , RH x 1
X22: =SUM(H22:W22) -> 39 | AA22: 20'TK x 3
X23: =SUM(H23:W23) -> 0
X24: =SUM(H24:W24) -> 0
X25: =SUM(H25:W25) -> 0
D26: S-TOTAL | H26: =SUM(H19:I25) -> 91 | J26: =SUM(J19:K25) -> 0 | L26: =SUM(L19:M25) -> 39 | N26: =SUM(N19:O25) -> 0 | P26: =SUM(P19:Q25) -> 1 | R26: =SUM(R19:S25) -> 0 | T26: =SUM(T19:U25) -> 110 | V26: =SUM(V19:W25) -> 0 | X26: =SUM(X19:Z25) -> 241
A27: SHIFT | D27: 1 TIME
D28: 1 TIME
A29: GRAND TOTAL | H29: =SUM(H18+H26+H27+H28) -> 184 | J29: =SUM(J18+J26+J27+J28) -> 0 | L29: =SUM(L18+L26+L27+L28) -> 202 | N29: =SUM(N18+N26+N27+N28) -> 0 | P29: =SUM(P18+P26+P27+P28) -> 1 | R29: =SUM(R18+R26+R27+R28) -> 0 | T29: =SUM(T18+T26+T27+T28) -> 110 | V29: =SUM(V18+V26+V27+V28) -> 0 | X29: =SUM(X18+X26+X27+X28) -> 497
A31: # WORKING PERIOD
A33: CRANE NO. | E33: FROM | K33: TO | Q33: HOURS | W33: REMARKS
A34: #1 (G/C) | E34: 0.35416667 | W34: COMMENCED LOAD.
A35: 27th | E35: 0.33333333 | K35: 0.5 | Q35: =IF(AND(NOT(ISBLANK(K35)),NOT(ISBLANK(E35))), IF(K35>E35,K35-E35,24-E35+K35), "") -> 0.16666667 | W35: LOAD. OF CONT'R
E36: 0.5 | K36: 0.54166667 | Q36: =IF(AND(NOT(ISBLANK(K36)),NOT(ISBLANK(E36))), IF(K36>E36,K36-E36,24-E36+K36), "") -> 0.041666667 | W36: MEAL TIME
E37: 0.54166667 | K37: 0.57291667 | Q37: =IF(AND(NOT(ISBLANK(K37)),NOT(ISBLANK(E37))), IF(K37>E37,K37-E37,24-E37+K37), "") -> 0.03125 | W37: LOAD. OF CONT'R
K38: =K37 -> 0.57291667 | Q38: =IF(AND(NOT(ISBLANK(K38)),NOT(ISBLANK(E38))), IF(K38>E38,K38-E38,24-E38+K38), "") | W38: COMPLETED LOAD. & GANG K/OFF
Q50: =IF(AND(NOT(ISBLANK(K50)),NOT(ISBLANK(E50))), IF(K50>E50,K50-E50,24-E50+K50), "")
Q51: =IF(AND(NOT(ISBLANK(K51)),NOT(ISBLANK(E51))), IF(K51>E51,K51-E51,24-E51+K51), "")
Q52: =SUM(Q34:V51) -> 0.23958333
A53: #2 (G/C) | E53: 0.045138889 | W53: COMMENCED DISCH.
E54: =E53 -> 0.045138889 | K54: 0.11111111 | Q54: =IF(AND(NOT(ISBLANK(K54)),NOT(ISBLANK(E54))), IF(K54>E54,K54-E54,24-E54+K54), "") -> 0.065972222 | W54: DISCH. OF CONT'R
E55: =K54 -> 0.11111111 | Q55: =IF(AND(NOT(ISBLANK(K55)),NOT(ISBLANK(E55))), IF(K55>E55,K55-E55,24-E55+K55), "") | W55: COMMENCED LOAD.
E56: =E55 -> 0.11111111 | K56: 0.13194444 | Q56: =IF(AND(NOT(ISBLANK(K56)),NOT(ISBLANK(E56))), IF(K56>E56,K56-E56,24-E56+K56), "") -> 0.020833333 | W56: LOAD. OF CONT'R
E57: =K56 -> 0.13194444 | K57: 0.14583333 | Q57: =IF(AND(NOT(ISBLANK(K57)),NOT(ISBLANK(E57))), IF(K57>E57,K57-E57,24-E57+K57), "") -> 0.013888889 | W57: DISCH. OF CONT'R
...
