Workbook

Sheet Final Work
A1: GREEN MARINE CO., LTD.
B2: FINAL WORKING REPORT (VOUCHER)
A4: M/V : | B4: SAWASDEE SPICA | F4: VOY # : | K4: DATE :
A6: PIER : | F6: BERTH : | K6: PORT : | L6: PYEONGTAEK, KOREA
A8: OPERATOR | B8: PORT | C8: FULL / EMPTY | D8: =+"DISCH ("&D74+E74+F74+G74+D75+E75+F75+G75&")" -> DISCH (0) | H8: =+"LOAD ("&H74+I74+J74+K74+H75+I75+J75+K75&")" -> LOAD (613) | L8: =+"SHIFT ("&L74+M74+N74+O74+L75+M75+N75+O75&")" -> SHIFT (0)
D9: 20' | E9: 40' | F9: HC | G9: 45' | H9: 20' | I9: 40' | J9: HC | K9: 45' | L9: 20' | M9: 40' | N9: HC | O9: 45'
C10: F
C11: E
C12: F
C13: E
C14: F
C15: E
C16: F
C17: E
C18: F
C19: E
C20: F
C21: E
... C73: E
A74: Total | D74: =SUM(D10,D12,D14,D16,D18,D20,D24,D26,D30,D32,D34,D36,D38,D40,D42,D44,D46,D48,D50,D52,D54,D56,D58,D60,D62,D64,D66,D68,D70,D72,D28) -> 0 | E74: =SUM(E10,E12,E14,E16,E18,E20,E24,E26,E30,E32,E34,E36,E38,E40,E42,E44,E46,E48,E50,E52,E54,E56,E58,E60,E62,E64,E66,E68,E70,E72,E28) -> 0 | F74: =SUM(F10,F12,F14,F16,F18,F20,F24,F26,F30,F32,F34,F36,F38,F40,F42,F44,F46,F48,F50,F52,F54,F56,F58,F60,F62,F64,F66,F68,F70,F72,F28) -> 0 | G74: =SUM(G10,G12,G14,G16,G18,G20,G24,G26,G30,G32,G34,G36,G38,G40,G42,G44,G46,G48,G50,G52,G54,G56,G58,G60,G62,G64,G66,G68,G70,G72,G28) -> 0 | H74: =SUM(H52,H48,H46,H44,H42,H40,H38,H32,H30,H26,H24,H22,H20,H18,H16,H14,H12,H10,H28,H34,H36) -> 56 | I74: =SUM(I52,I48,I46,I44,I42,I40,I38,I32,I30,I26,I24,I22,I20,I18,I16,I14,I12,I10,I28,I34,I36) -> 0 | J74: =SUM(J52,J48,J46,J44,J42,J40,J38,J32,J30,J26,J24,J22,J20,J18,J16,J14,J12,J10,J28,J34,J36) -> 32 | K74: =SUM(K52,K48,K46,K44,K42,K40,K38,K32,K30,K26,K24,K22,K20,K18,K16,K14,K12,K10,K28,K34,K36) -> 0 | L74: =SUM(L10,L12,L14,L16,L18,L20,L24,L26,L30,L32,L34,L36,L38,L40,L42,L44,L46,L48,L50,L52,L54,L56,L58,L60,L62,L64,L66,L68,L70,L72,L28) -> 0 | M74: =SUM(M10,M12,M14,M16,M18,M20,M24,M26,M30,M32,M34,M36,M38,M40,M42,M44,M46,M48,M50,M52,M54,M56,M58,M60,M62,M64,M66,M68,M70,M72,M28) -> 0 | N74: =SUM(N10,N12,N14,N16,N18,N20,N24,N26,N30,N32,N34,N36,N38,N40,N42,N44,N46,N48,N50,N52,N54,N56,N58,N60,N62,N64,N66,N68,N70,N72,N28) -> 0 | O74: =SUM(O10,O12,O14,O16,O18,O20,O24,O26,O30,O32,O34,O36,O38,O40,O42,O44,O46,O48,O50,O52,O54,O56,O58,O60,O62,O64,O66,O68,O70,O72,O28) -> 0
D75: =SUM(D11,D13,D15,D17,D19,D21,D25,D27,D31,D33,D35,D37,D39,D41,D43,D45,D47,D49,D51,D53,D55,D57,D59,D61,D63,D65,D67,D69,D71,D73,D29) -> 0 | E75: =SUM(E11,E13,E15,E17,E19,E21,E25,E27,E31,E33,E35,E37,E39,E41,E43,E45,E47,E49,E51,E53,E55,E57,E59,E61,E63,E65,E67,E69,E71,E73,E29) -> 0 | F75: =SUM(F11,F13,F15,F17,F19,F21,F25,F27,F31,F33,F35,F37,F39,F41,F43,F45,F47,F49,F51,F53,F55,F57,F59,F61,F63,F65,F67,F69,F71,F73,F29) -> 0 | G75: =SUM(G11,G13,G15,G17,G19,G21,G25,G27,G31,G33,G35,G37,G39,G41,G43,G45,G47,G49,G51,G53,G55,G57,G59,G61,G63,G65,G67,G69,G71,G73,G29) -> 0 | H75: =SUM(H53,H49,H47,H45,H43,H41,H39,H33,H31,H27,H25,H23,H21,H19,H17,H15,H13,H11,H35,H37) -> 26 | I75: =SUM(I53,I49,I47,I45,I43,I41,I39,I33,I31,I27,I25,I23,I21,I19,I17,I15,I13,I11,I35,I37) -> 0 | J75: =SUM(J53,J49,J47,J45,J43,J41,J39,J33,J31,J27,J25,J23,J21,J19,J17,J15,J13,J11,J35,J37) -> 499 | K75: =SUM(K53,K49,K47,K45,K43,K41,K39,K33,K31,K27,K25,K23,K21,K19,K17,K15,K13,K11,K35,K37) -> 0 | L75: =SUM(L11,L13,L15,L17,L19,L21,L25,L27,L31,L33,L35,L37,L39,L41,L43,L45,L47,L49,L51,L53,L55,L57,L59,L61,L63,L65,L67,L69,L71,L73,L29) -> 0 | M75: =SUM(M11,M13,M15,M17,M19,M21,M25,M27,M31,M33,M35,M37,M39,M41,M43,M45,M47,M49,M51,M53,M55,M57,M59,M61,M63,M65,M67,M69,M71,M73,M29) -> 0 | N75: =SUM(N11,N13,N15,N17,N19,N21,N25,N27,N31,N33,N35,N37,N39,N41,N43,N45,N47,N49,N51,N53,N55,N57,N59,N61,N63,N65,N67,N69,N71,N73,N29) -> 0 | O75: =SUM(O11,O13,O15,O17,O19,O21,O25,O27,O31,O33,O35,O37,O39,O41,O43,O45,O47,O49,O51,O53,O55,O57,O59,O61,O63,O65,O67,O69,O71,O73,O29) -> 0
A77: Remarks : Discharging | H77: Remarks : Loading
A90: CHIEF CHECKER | J90: CHIEF OFFICER

Sheet Time Sheet
A1: GREEN MARINE CO., LTD.
A2: PYEONGTAEK, KOREA
C3: T I M E S H E E T
A6: M / V : | C6: VOY # : | G6: DATE : | H6: ='Final Work'!선적종료일 -> 46214
A8: PIER : | C8: BERTH : | G8: WEATHER :
H10: PORT : PYEONGTAEK, KOREA
A12: T I M E | C12: R E M A R K S
A13: 10th
A32: 11th
A46: CHIEF CHECKER

Sheet OS-OUT
A1: GREEN MARINE CO., LTD.
A2: PYEONGTAEK, KOREA
A4: CARGO OVERAGE & SHORTAGE REPORT (LOAD)
A6: M / V : | B6: ='Final Work'!모선이름 -> SAWASDEE SPICA | G6: VOY. NO.: | K6: DATE :
A8: PORT : | B8: PYEONGTAEK, KOREA | G8: PIER : | K8: BERTH :
A10: B/L NO. | B10: MARKS (PORT) | D10: DESCRIPTION | G10: TYPE OF | H10: MANIFESTED | J10: LOADED | K10: OVER | L10: SHORT | M10: REMARKS
G11: PKGS
D25: T O T A L | G25: VAN | H25: =SUM(H11:I24) -> 613 | J25: =SUM(J11:J24) -> 613 | K25: NIL | L25: NIL
A37: CHIEF CHECKER | G37: STEVEDORE PCTC | L37: CHIEF OFFICER

Sheet OS-IN
A1: GREEN MARINE CO., LTD.
A2: PYEONGTAEK, KOREA
A4: CARGO OVERAGE & SHORTAGE REPORT (DISCH)
A6: M / V : | B6: ='Final Work'!모선이름 -> SAWASDEE SPICA | G6: VOY. NO.: | K6: DATE :
A8: PORT : | B8: PYEONGTAEK, KOREA | G8: PIER : | K8: BERTH :
A10: B/L NO. | B10: MARKS (PORT) | D10: DESCRIPTION | G10: TYPE OF | H10: MANIFESTED | J10: DISCHARGED | K10: OVER | L10: SHORT | M10: REMARKS
G11: PKGS
D23: T O T A L | G23: VAN | H23: =SUM(H12:I22) -> 297 | J23: =SUM(J12:J22) -> 297 | K23: NIL | L23: NIL
A32: CHIEF CHECKER | G32: STEVEDORE PCTC | L32: CHIEF OFFICER

Sheet DM-IN
A1: GREEN MARINE CO., LTD.
A2: PYEONGTAEK, KOREA
A4: CARGO DAMAGE REPORT
A6: M / V : | B6: ='Final Work'!모선이름 -> SAWASDEE SPICA | H6: VOY. NO. : | J6: ='OS-IN'!H6 -> 2605N | O6: DATE : | P6: ='OS-IN'!L6 -> 46213
A8: PORT : | B8: PYEONGTAEK, KOREA | H8: PIER : | J8: PCTC | O8: BERTH: | P8: ='Final Work'!작업선석 -> 7
A10: PORT | B10: B/L NO. | C10: MARKS | F10: CONTENTS | J10: NO. OF | K10: TYPE | L10: EXCEPTION ( Found In Stow )
J11: PKGS
A32: CHIEF CHECKER | I32: STEVEDORE PCTC | O32: CHIEF OFFICER

Sheet DM-OUT
A1: GREEN MARINE CO., LTD.
A2: PYEONGTAEK, KOREA
A4: CARGO DAMAGE REPORT
A6: M / V : | B6: ='OS-OUT'!모선이름 -> SAWASDEE SPICA | H6: VOY. NO. : | J6: ='OS-OUT'!H6 -> 2606S | O6: DATE : | P6: ='OS-OUT'!L6 -> 46214
A8: PORT : | B8: PYEONGTAEK, KOREA | H8: PIER : | J8: PCTC | O8: BERTH : | P8: ='Final Work'!작업선석 -> 7
A10: PORT | B10: B/L NO. | C10: MARKS | F10: CONTENTS | J10: NO. OF | K10: TYPE | L10: EXCEPTION ( Prior To Load )
J11: PKGS
A32: CHIEF CHECKER | I32: STEVEDORE PCTC | O32: CHIEF OFFICER

Sheet Act. Cntr-Seal No List
A1: GREEN MARINE CO., LTD.
A2: PYEONGTAEK, KOREA
A4: M / V : | B4: SAWASDEE SPICA | F4: DATE :
A6: VOY # : | B6: ='OS-OUT'!H6 -> 2606S | F6: PORT : | G6: PYEONGTAEK, KOREA
B8: ACTUAL CONTAINER & SEAL NUMBER LIST
H9: LOAD'
A10: MANIFEST | D10: SIZE | E10: ACTUAL | G10: RESEAL NO. | H10: REMARKS
A11: CONT'R NO. | C11: SEAL NO. | E11: CONT'R NO. | F11: SEAL NO.
A33: 20FT | B33: FULL
B34: EMPTY
A35: 40FT | B35: FULL
B36: EMPTY
A37: TOTAL | C37: =SUM(C33:C36) -> 0 | G37: CHIEF CHECKER

Sheet RF Condition Report
A1: GREEN MARINE O., LTD.
A2: PYEONGTAEK, KOREA
A4: REEFER ONTAINER ONDITION REPORT
A5: Disharging / Loading
I6: ( 1/1 )
A7: M/V : SAWASDEE SPICA | D7: VOY # : | E7: ='OS-OUT'!H6 -> 2606S | G7: DATE : | H7: ='OS-OUT'!L6 -> 46214
A8: PIER : PCTC | D8: BERTH : | E8: 7 | G8: PORT : | H8: PYEONGTAEK, KOREA
A10: ONTAINER NO. | B10: SEAL NO. | C10: SIZE | D10: LOATION | F10: TEMPERATURE | H10: TIME | I10: REMARKS
D11: Bay/Slot/Tier | F11: Setting | G11: Atual | H11: Plug In / Out

Sheet Performance
A1: GREEN MARINE CO., LTD
A2: PYEONGTAEK, KOREA
A4: PERFORMANCE REPORT
A6: M / V : | D6: ='Final Work'!B4 -> SAWASDEE SPICA | O6: VOY # : | R6: ='Final Work'!G4 -> 2606S | Y6: DATE : | AB6: ='Final Work'!L4 -> 46214
A8: PIER : | D8: PCTC | O8: BERTH : | R8: ='Final Work'!G6 -> 7 | Y8: PORT : | AB8: PYEONGTAEK, KOREA
A10: Status | H10: FULL | P10: EMPTY | X10: TOTAL | AA10: REMARKS
A11: Description | H11: 20' | J11: 40' | L11: HC | N11: 45' | P11: 20' | R11: 40' | T11: HC | V11: 45'
A12: IN BOUND | X12: =SUM(H12:W12) -> 0
X13: =SUM(H13:W13) -> 0
X14: =SUM(H14:W14) -> 0
X15: =SUM(H15:W15) -> 0
X16: =SUM(H16:W16) -> 0
X17: =SUM(H17:W17) -> 0
X18: =SUM(H18:W18) -> 0
D19: S-TOTAL | H19: =SUM(H12:I18) -> 0 | J19: =SUM(J12:K18) -> 0 | L19: =SUM(L12:M18) -> 0 | N19: =SUM(N12:O18) -> 0 | P19: =SUM(P12:Q18) -> 0 | R19: =SUM(R12:S18) -> 0 | T19: =SUM(T12:U18) -> 0 | V19: =SUM(V12:W18) -> 0 | X19: =SUM(X12:Z18) -> 0
A20: OUT BOUND | X20: =SUM(H20:W20) -> 389
X21: =SUM(H21:W21) -> 223 | AA21: 20'DG x 3
X22: =SUM(H22:W22) -> 1
X23: =SUM(H23:W23) -> 0
X24: =SUM(H24:W24) -> 0
X25: =SUM(H25:W25) -> 0
X26: =SUM(H26:W26) -> 0
D27: S-TOTAL | H27: =SUM(H20:I26) -> 56 | J27: =SUM(J20:K26) -> 0 | L27: =SUM(L20:M26) -> 32 | N27: =SUM(N20:O26) -> 0 | P27: =SUM(P20:Q26) -> 26 | R27: =SUM(R20:S26) -> 0 | T27: =SUM(T20:U26) -> 499 | V27: =SUM(V20:W26) -> 0 | X27: =SUM(X20:Z26) -> 613
A28: SHIFT | D28: 1 TIME
D29: 1 TIME
A30: GRAND TOTAL | H30: =SUM(H19+H27+H28+H29) -> 56 | J30: =SUM(J19+J27+J28+J29) -> 0 | L30: =SUM(L19+L27+L28+L29) -> 32 | N30: =SUM(N19+N27+N28+N29) -> 0 | P30: =SUM(P19+P27+P28+P29) -> 26 | R30: =SUM(R19+R27+R28+R29) -> 0 | T30: =SUM(T19+T27+T28+T29) -> 499 | V30: =SUM(V19+V27+V28+V29) -> 0 | X30: =SUM(X19+X27+X28+X29) -> 613
A32: # WORKING PERIOD
A34: CRANE NO. | E34: FROM | K34: TO | Q34: HOURS | W34: REMARKS
A35: #1 (G/C) | E35: 0.40277778 | Q35: =IF(AND(NOT(ISBLANK(K35)),NOT(ISBLANK(E35))), IF(K35>E35,K35-E35,24-E35+K35), "") | W35: COMMENCED DISCH.
A36: 30th | E36: =E35 -> 0.40277778 | K36: 0.5 | Q36: =IF(AND(NOT(ISBLANK(K36)),NOT(ISBLANK(E36))), IF(K36>E36,K36-E36,24-E36+K36), "") -> 0.097222222 | W36: DISCH. OF CONT'R
E37: =K36 -> 0.5 | K37: 0.54166667 | Q37: =IF(AND(NOT(ISBLANK(K37)),NOT(ISBLANK(E37))), IF(K37>E37,K37-E37,24-E37+K37), "") -> 0.041666667 | W37: MEAL TIME
E38: =K37 -> 0.54166667 | K38: 0.69791667 | Q38: =IF(AND(NOT(ISBLANK(K38)),NOT(ISBLANK(E38))), IF(K38>E38,K38-E38,24-E38+K38), "") -> 0.15625 | W38: DISCH. OF CONT'R
K39: =K38 -> 0.69791667 | Q39: =IF(AND(NOT(ISBLANK(K39)),NOT(ISBLANK(E39))), IF(K39>E39,K39-E39,24-E39+K39), "") | W39: COMPLETED DISCH.
E40: =K39 -> 0.69791667 | Q40: =IF(AND(NOT(ISBLANK(K40)),NOT(ISBLANK(E40))), IF(K40>E40,K40-E40,24-E40+K40), "") | W40: COMMENCED LOAD.
E41: =E40 -> 0.69791667 | K41: 0.72916667 | Q41: =IF(AND(NOT(ISBLANK(K41)),NOT(ISBLANK(E41))), IF(K41>E41,K41-E41,24-E41+K41), "") -> 0.03125 | W41: LOAD. OF CONT'R
E42: =K41 -> 0.72916667 | K42: 0.79166667 | Q42: =IF(AND(NOT(ISBLANK(K42)),NOT(ISBLANK(E42))), IF(K42>E42,K42-E42,24-E42+K42), "") -> 0.0625 | W42: MEAL TIME
E43: =K42 -> 0.79166667 | K43: 0.96875 | Q43: =IF(AND(NOT(ISBLANK(K43)),NOT(ISBLANK(E43))), IF(K43>E43,K43-E43,24-E43+K43), "") -> 0.17708333 | W43: LOAD. OF CONT'R
K44: =K43 -> 0.96875 | Q44: =IF(AND(NOT(ISBLANK(K44)),NOT(ISBLANK(E44))), IF(K44>E44,K44-E44,24-E44+K44), "") | W44: COMPLETED LOAD. & GANG K/OFF
Q45: =IF(AND(NOT(ISBLANK(K45)),NOT(ISBLANK(E45))), IF(K45>E45,K45-E45,24-E45+K45), "")
Q46: =IF(AND(NOT(ISBLANK(K46)),NOT(ISBLANK(E46))), IF(K46>E46,K46-E46,24-E46+K46), "")
...

Sheet SHIFTING
A1: GREEN MARINE CO., LTD.
A2: SHIFTING REPORT
A4: M.V. : SAWASDEE SPICA | G4: VOY # : 2514N/2514N | K4: DATE : 2026-01-31 | N4: PORT : PYEONGTAEK, KOREA
A6: NO | B6: CON'T NO | C6: TYPE | D6: F/E | E6: W/T | F6: OPR | G6: OLD | H6: NEW | I6: POD | J6: POL | K6: A/C | L6: REASON | M6: SHIFT | N6: REMARK
G7: POSN | H7: POSN
