Workbook

Sheet Final Work
A1: GREEN MARINE CO., LTD.
C2: FINAL WORKING REPORT(VOUCHER)
A4: M/V : | B4: TIAN HAI PING ZE | E4: VOY # : | J4: DATE : | L4: 46228
A6: PIER : | B6: PNCT | F6: BERTH : | J6: PORT : | L6: PYEONGTAEK, KOREA
A8: OPR | B8: PORT | C8: FULL (F) | D8: =+"DISCH ( "&+D38+E38+F38+G38+D39+E39+F39+G39&" )" -> DISCH ( 276 ) | H8: =+"LOAD ( "&H38+I38+J38+K38+H39+I39+J39+K39&" )" -> LOAD ( 227 ) | L8: =+"SHIFT ( "&L38+M38+O38+L39+M39+O39&" )" -> SHIFT ( 0 )
C9: EMPTY(E) | D9: 20' | E9: 40' | F9: HC | G9: 45' | H9: 20' | I9: 40' | J9: HC | K9: 45' | L9: 20' | M9: 40' | N9: HC | O9: 45'
A10: TJM | B10: NGB | C10: F
C11: E
B12: SHA | C12: F
C13: E
B14: (DWS) NGB | C14: F
C15: E
B16: (DWS) SHA | C16: F
C17: E
B18: (MAS) NGB | C18: F
C19: E
B20: (MAS) SHA | C20: F
C21: E
B22: Total | C22: F | D22: =+D10+D12+D18+D20+D14+D16 -> 83 | E22: =+E10+E12+E18+E20+E14+E16 -> 2 | F22: =+F10+F12+F18+F20+F14+F16 -> 147 | G22: =+G10+G12+G18+G20+G14+G16 -> 0 | H22: =+H10+H12+H18+H20+H14+H16 -> 21 | I22: =+I10+I12+I18+I20+I14+I16 -> 0 | J22: =+J10+J12+J18+J20+J14+J16 -> 122 | K22: =+K10+K12+K18+K20+K14+K16 -> 0 | ... O22: =+O10+O12+O18+O20+O14+O16 -> 0
C23: E | D23: =+D11+D13+D19+D21+D15+D17 -> 0 | E23: =+E11+E13+E19+E21+E15+E17 -> 0 | F23: =+F11+F13+F19+F21+F15+F17 -> 0 | G23: =+G11+G13+G19+G21+G15+G17 -> 0 | H23: =+H11+H13+H19+H21+H15+H17 -> 36 | I23: =+I11+I13+I19+I21+I15+I17 -> 1 | J23: =+J11+J13+J19+J21+J15+J17 -> 10 | K23: =+K11+K13+K19+K21+K15+K17 -> 0 | ... O23: =+O11+O13+O19+O21+O15+O17 -> 0
A24: EAS | B24: NGB | C24: F
C25: E
B26: SHA | C26: F
C27: E
B28: Total | C28: F | D28: =+D24+D26 -> 20 | E28: =+E24+E26 -> 0 | F28: =+F24+F26 -> 24 | G28: =+G24+G26 -> 0 | H28: =+H24+H26 -> 6 | I28: =+I24+I26 -> 0 | J28: =+J24+J26 -> 31 | K28: =+K24+K26 -> 0 | ... O28: =+O24+O26 -> 0
C29: E | D29: =+D25+D27 -> 0 | E29: =+E25+E27 -> 0 | F29: =+F25+F27 -> 0 | G29: =+G25+G27 -> 0 | H29: =+H25+H27 -> 0 | I29: =+I25+I27 -> 0 | J29: =+J25+J27 -> 0 | K29: =+K25+K27 -> 0 | ... O29: =+O25+O27 -> 0
B30: NGB | C30: F
C31: E
B32: SHA | C32: F
C33: E
B34: Total | C34: F | D34: =+D30+D32 -> 0 | E34: =+E30+E32 -> 0 | F34: =+F30+F32 -> 0 | G34: =+G30+G32 -> 0 | H34: =+H30+H32 -> 0 | I34: =+I30+I32 -> 0 | J34: =+J30+J32 -> 0 | K34: =+K30+K32 -> 0 | ... O34: =+O30+O32 -> 0
C35: E | D35: =+D31+D33 -> 0 | E35: =+E31+E33 -> 0 | F35: =+F31+F33 -> 0 | G35: =+G31+G33 -> 0 | H35: =+H31+H33 -> 0 | I35: =+I31+I33 -> 0 | J35: =+J31+J33 -> 0 | K35: =+K31+K33 -> 0 | ... O35: =+O31+O33 -> 0
B36: NGB | C36: F
C37: E
A38: G. Total | C38: F | D38: =+D22+D28+D34 -> 103 | E38: =+E22+E28+E34 -> 2 | F38: =+F22+F28+F34 -> 171 | G38: =+G22+G28+G34 -> 0 | H38: =+H22+H28+H34 -> 27 | I38: =+I22+I28+I34 -> 0 | J38: =+J22+J28+J34 -> 153 | K38: =+K22+K28+K34 -> 0 | ... O38: =+O22+O28+O34 -> 0
C39: E | D39: =+D23+D29+D35 -> 0 | E39: =+E23+E29+E35 -> 0 | F39: =+F23+F29+F35 -> 0 | G39: =+G23+G29+G35 -> 0 | H39: =+H23+H29+H35 -> 36 | I39: =+I23+I29+I35 -> 1 | J39: =+J23+J29+J35 -> 10 | K39: =+K23+K29+K35 -> 0 | ... O39: =+O23+O29+O35 -> 0
A41: Remarks : Discharging | H41: Remarks : Loading
A50: CHIEF CHECKER | J50: CHIEF OFFICER

Sheet Time sheet
A1: GREEN MARINE CO., LTD.
A2: PYEONGTAEK, KOREA
C3: T I M E S H E E T
A6: M/V : | B6: ='Final Work'!B4 -> TIAN HAI PING ZE | C6: ='Final Work'!E4 -> VOY # : 2022E / 2022W | G6: DATE : | H6: ='Final Work'!L4 -> 46228
A8: PIER : | B8: PNCT | D8: BERTH : | E8: ='Final Work'!G6 -> 15 | G8: WEATHER : | H8: Fine
H10: PORT : PYEONGTAEK, KOREA
A11: T I M E | C11: R E M A R K S
A12: 24th
A19: 25th
A41: CHIEF CHECKER

Sheet OS-IN
A1: GREEN MARINE CO., LTD.
A2: PYEONGTAEK, KOREA
A4: CARGO OVERAGE & SHORTAGE REPORT (DISCH)
A6: M / V : | B6: ='Final Work'!B4 -> TIAN HAI PING ZE | G6: VOY. NO.: | H6: 2022E | K6: DATE : | L6: 46227
A8: PORT : | B8: PYEONGTAEK, KOREA | G8: PIER : | H8: PNCT | K8: BERTH : | L8: ='Final Work'!G6 -> 15
A10: B/L NO. | B10: MARKS (PORT) | D10: DESCRIPTION | G10: TYPE OF | H10: MANIFESTED | J10: DISCHARGED | K10: OVER | L10: SHORT | M10: REMARKS
G11: PKGS
J12: =SUM(H12) -> 33
J13: =SUM(H13) -> 61
J14: =SUM(H14) -> 70
J15: =SUM(H15) -> 2
J16: =SUM(H16) -> 110
J17: =SUM(H17) -> 0
D18: T O T A L | G18: VAN | H18: =SUM(H12:I17) -> 276 | J18: =SUM(J12:J17) -> 276 | K18: NIL | L18: NIL
A29: CHIEF CHECKER | G29: STEVEDORE | L29: CHIEF OFFICER

Sheet DM-IN
A1: GREEN MARINE CO., LTD.
A2: PYEONGTAEK, KOREA
A4: CARGO DAMAGE REPORT
A6: M / V : | B6: ='Final Work'!B4 -> TIAN HAI PING ZE | I6: VOY. NO. : | K6: ='OS-IN'!H6 -> 2022E | O6: DATE : | P6: ='OS-IN'!L6 -> 46227
A8: PORT : | B8: PYEONGTAEK, KOREA | I8: PIER : | K8: PNCT | O8: BERTH : | P8: =+'Final Work'!G6 -> 15
A10: PORT | B10: B/L NO. | C10: MARKS | F10: CONTENTS | J10: NO. OF | K10: TYPE | L10: EXCEPTION ( Found in stow )
J11: PKGS
A12: SHA | B12: TJM | C12: WFHU5204808 | F12: 40' FULL CONT'R | J12: 1 | K12: VAN | L12: TOP PANEL 1 POINT TORN ( 4 x 4 )Cm
A13: SHA | B13: TJM | C13: PHRU8187790 | F13: 40' FULL CONT'R | J13: 1 | K13: VAN | L13: LEFT SIDE PANEL 1 POINT DENT ( 100 x 45 x 8 )Cm
A31: CHIEF CHECKER | I31: STEVEDORE | O31: CHIEF OFFICER

Sheet OS-OUT
A1: GREEN MARINE CO., LTD.
A2: PYEONGTAEK, KOREA
A4: CARGO OVERAGE & SHORTAGE REPORT (LOAD)
A6: M / V : | B6: ='Final Work'!B4 -> TIAN HAI PING ZE | G6: VOY. NO.: | H6: 2022W | K6: DATE : | L6: ='Final Work'!L4:O4 -> 46228
A8: PORT : | B8: PYEONGTAEK, KOREA | G8: PIER : | H8: PNCT | K8: BERTH : | L8: ='Final Work'!G6 -> 15
A10: B/L NO. | B10: MARKS (PORT) | D10: DESCRIPTION | G10: TYPE OF | H10: MANIFESTED | J10: LOADED | K10: OVER | L10: SHORT | M10: REMARKS
G11: PKGS
J12: =SUM(H12) -> 14
J13: =SUM(H13) -> 20
J14: =SUM(H14) -> 0
J15: =SUM(H15) -> 70
J16: =SUM(H16) -> 0
J17: =SUM(H17) -> 10
J18: =SUM(H18) -> 13
J19: =SUM(H19) -> 16
J20: =SUM(H20) -> 1
J21: =SUM(H21) -> 83
D22: T O T A L | G22: VAN | H22: =SUM(H12:I21) -> 227 | J22: =SUM(J12:J21) -> 227 | K22: NIL | L22: NIL
A29: CHIEF CHECKER | G29: STEVEDORE | L29: CHIEF OFFICER

Sheet DM-OUT
A1: GREEN MARINE CO., LTD.
A2: PYEONGTAEK, KOREA
A4: CARGO DAMAGE REPORT
A6: M / V : | B6: ='Final Work'!B4 -> TIAN HAI PING ZE | I6: VOY. NO. : | K6: ='OS-OUT'!H6 -> 2022W | O6: DATE : | P6: ='Final Work'!L4 -> 46228
A8: PORT : | B8: PYEONGTAEK, KOREA | I8: PIER : | K8: PNCT | O8: BERTH : | P8: =+'Final Work'!G6 -> 15
A10: PORT | B10: B/L NO. | C10: MARKS | F10: CONTENTS | J10: NO. OF | K10: TYPE | L10: EXCEPTION ( Prior To Load )
J11: PKGS
A31: CHIEF CHECKER | I31: STEVEDORE | O31: CHIEF OFFICER

Sheet DAMAGE REPORT
A1: GREEN MARINE CO., LTD.
A2: PYEONGTAEK, KOREA
A4: CONTAINER DAMAGED REPORT
A6: M / V : | B6: ='Final Work'!B4 -> TIAN HAI PING ZE | E6: VOY. NO. : | G6: ='OS-IN'!H6 -> 2022E | J6: DATE : | K6: ='OS-IN'!L6 -> 46227
A8: CONTAINER NO : | C8: WFHU5204808 | E8: SEAL NO. : | G8: FULL | J8: SIZE : | K8: 20' | L8: 40' | M8: 45'
A9: OPERATOR : | C9: SHA-TJM
M10: PORT : PYEONGTAEK, KOREA
A28: Description of Damage :
B29: ( Found in stow )
B30: TOP PANEL 1 POINT TORN ( 4 x 4 )Cm
A35: SYMBOLS
A36: B | B36: BO | C36: BU | D36: C | E36: D | F36: DO | G36: H | H36: M | I36: O | J36: P | K36: R | L36: S | M36: T
A37: Broken | B37: Bulged out | C37: Buckled | D37: Cut | E37: Dent | F37: Distorted | G37: Hole | H37: Miss | I37: Burned out | J37: Patch | K37: Rusty | L37: Scratch | M37: Torn
A44: CHIEF CHECKER | F44: STEVEDORE | K44: CHIEF OFFICER
A45: GREEN MARINE CO., LTD.
A46: PYEONGTAEK, KOREA
A48: CONTAINER DAMAGED REPORT
A50: M / V : | B50: ='Final Work'!B4 -> TIAN HAI PING ZE | E50: VOY. NO. : | G50: ='OS-IN'!H6 -> 2022E | J50: DATE : | K50: ='OS-IN'!L6 -> 46227
A52: CONTAINER NO : | C52: PHRU8187790 | E52: SEAL NO. : | G52: FULL | J52: SIZE : | K52: 20' | L52: 40' | M52: 45'
A53: OPERATOR : | C53: SHA-TJM
M54: PORT : PYEONGTAEK, KOREA
A72: Description of Damage :
B73: ( Found in stow )
B74: LEFT SIDE PANEL 1 POINT DENT ( 100 x 45 x 8 )Cm
A79: SYMBOLS
A80: B | B80: BO | C80: BU | D80: C | E80: D | F80: DO | G80: H | H80: M | I80: O | J80: P | K80: R | L80: S | M80: T
A81: Broken | B81: Bulged out | C81: Buckled | D81: Cut | E81: Dent | F81: Distorted | G81: Hole | H81: Miss | I81: Burned out | J81: Patch | K81: Rusty | L81: Scratch | M81: Torn
A88: CHIEF CHECKER | F88: STEVEDORE | K88: CHIEF OFFICER

Sheet Act. Cntr-Seal No List
A1: GREEN MARINE CO., LTD.
A2: PYEONGTAEK, KOREA
A4: M / V : | B4: ='Final Work'!B4 -> TIAN HAI PING ZE | E4: DATE : | F4: ='OS-IN'!L6 -> 46227
A6: VOY.NO. : | B6: ='OS-IN'!H6 -> 2022E | E6: PORT : | F6: PYEONGTAEK, KOREA
B8: ACTUAL CONTAINER & SEAL NUMBER LIST
G9: DISCH.
A10: MANIFEST | C10: SIZE | D10: ACTUAL | F10: RESEAL NO. | G10: REMARKS
A11: CONT'R NO. | B11: SEAL NO. | D11: CONT'R NO. | E11: SEAL NO.
A33: 20FT FULL
A34: 20FT EMPTY
A35: 40FT FULL
A36: 40FT EMPTY
A37: TOTAL | B37: =SUM(B33:B36) -> 0 | F37: CHIEF CHECKER
A38: GREEN MARINE CO., LTD.
A39: PYEONGTAEK, KOREA
A41: M / V : | B41: =B4 -> TIAN HAI PING ZE | E41: DATE : | F41: ='Final Work'!L4 -> 46228
A43: VOY.NO. : | B43: ='OS-OUT'!H6 -> 2022W | E43: PORT : | F43: PYEONGTAEK, KOREA
B45: ACTUAL CONTAINER & SEAL NUMBER LIST
G46: LOAD.
A47: MANIFEST | C47: SIZE | D47: ACTUAL | F47: RESEAL NO. | G47: REMARKS
A48: CONT'R NO. | B48: SEAL NO. | D48: CONT'R NO. | E48: SEAL NO.
A49: -NIL-
A70: 20FT FULL
A71: 20FT EMPTY
A72: 40FT FULL
A73: 40FT EMPTY
A74: TOTAL | B74: =SUM(B70:B73) -> 0 | F74: CHIEF CHECKER

Sheet RF condition report
A1: GREEN MARINE CO., LTD.
A2: PYEONGTAEK, KOREA
A4: REEFER CONTAINER CONDITION REPORT
A5: Discharging / Loading
I6: 1/1
A7: M/V : TIAN HAI PING ZE | D7: VOY # : | E7: ='OS-IN'!H6 -> 2022E | G7: DATE : | H7: ='OS-IN'!L6 -> 46227
A8: PIER : PNCT | D8: BERTH : | E8: ='Final Work'!G6 -> 15 | G8: PORT : | H8: PYEONGTAEK, KOREA
A10: CONTAINER NO. | B10: SEAL NO. | C10: SIZE | D10: LOCATION | F10: TEMPERATURE | H10: TIME | I10: REMARKS
D11: Bay/Slot/Tier | F11: Setting | G11: Actual | H11: Plug In / Out
A42: CHIEF CHECKER | D42: STEVEDORE | H42: CHIEF OFFICER
A43: GREEN MARINE CO., LTD.
A44: PYEONGTAEK, KOREA
A46: REEFER CONTAINER CONDITION REPORT
A47: Discharging / Loading
I48: 1/1
A49: =A7 -> M/V : TIAN HAI PING ZE | D49: VOY # : | E49: ='OS-OUT'!H6 -> 2022W | G49: DATE : | H49: ='Final Work'!L4 -> 46228
A50: PIER : PNCT | D50: BERTH : | E50: ='Final Work'!G6 -> 15 | G50: PORT : | H50: PYEONGTAEK, KOREA
A52: CONTAINER NO. | B52: SEAL NO. | C52: SIZE | D52: LOCATION | F52: TEMPERATURE | H52: TIME | I52: REMARKS
D53: Bay/Slot/Tier | F53: Setting | G53: Actual | H53: Plug In / Out
A54: -NIL-
A75: < CY 보관지침 >
A76: 1. 최초 화주로 부터 지정된 온도(SETTING 온도를 말하며 수입목록 혹은 BAY PLAN에
A77: 표기된 온도)는 그 적정 온도를 유지하고 있는지 4시간마다 확인하여 기록 보관해야한다.
A78: 2. 온도를 지정하는 지시 및 표기가 없을 경우 일반적으로 채용되고 있는
A79: 냉동/냉장 화물의 운송온도를 기준으로 한다.
A80: 3. 만일 온도 이상 및 기타 기기의 이상이 발견될 시는 즉시 OPERATOR에게 통보하여야한다.
A84: CHIEF CHECKER | D84: STEVEDORE | H84: CHIEF OFFICER

Sheet PERFORMANCE
A1: GREEN MARINE CO., LTD
A2: PYEONGTAEK, KOREA
A4: PERFORMANCE REPORT
A6: M/V : | D6: ='Final Work'!B4 -> TIAN HAI PING ZE | N6: ='Final Work'!E4 -> VOY # : 2022E / 2022W | Y6: DATE : | AB6: ='Final Work'!L4 -> 46228
A8: PIER : | D8: PNCT | O8: BERTH : | R8: ='Final Work'!G6 -> 15 | Y8: PORT : | AB8: PYEONGTAEK, KOREA
A10: Status | H10: FULL | P10: EMPTY | X10: TOTAL | AA10: REMARKS
A11: Description | H11: 20' | J11: 40' | L11: HC | N11: 45' | P11: 20' | R11: 40' | T11: HC | V11: 45'
A12: IN BOUND | D12: TJM | H12: 83 | J12: 2 | L12: 147 | X12: =SUM(H12:W12) -> 232 | AA12: 20'DG x 5 , 40'DG x 3 ( FR x 2 )
D13: EAS | H13: 20 | L13: 24 | X13: =SUM(H13:W13) -> 44 | AA13: 40'RH x 2
D14: DWS | X14: =SUM(H14:W14) -> 0
D15: MAS | X15: =SUM(H15:W15) -> 0
X16: =SUM(H16:W16) -> 0
D17: S-TOTAL | H17: =SUM(H12:I16) -> 103 | J17: =SUM(J12:K16) -> 2 | L17: =SUM(L12:M16) -> 171 | N17: =SUM(N12:O16) -> 0 | P17: =SUM(P12:Q16) -> 0 | R17: =SUM(R12:S16) -> 0 | T17: =SUM(T12:U16) -> 0 | V17: =SUM(V12:W16) -> 0 | X17: =SUM(X12:Z16) -> 276
A18: OUT BOUND | D18: TJM | H18: 21 | L18: 122 | P18: 36 | R18: 1 | T18: 10 | X18: =SUM(H18:W18) -> 190
D19: EAS | H19: 6 | L19: 31 | X19: =SUM(H19:W19) -> 37
D20: DWS | X20: =SUM(H20:W20) -> 0
D21: MAS | X21: =SUM(H21:W21) -> 0
X22: =SUM(H22:W22) -> 0
D23: S-TOTAL | H23: =SUM(H18:I22) -> 27 | J23: =SUM(J18:K22) -> 0 | L23: =SUM(L18:M22) -> 153 | N23: =SUM(N18:O22) -> 0 | P23: =SUM(P18:Q22) -> 36 | R23: =SUM(R18:S22) -> 1 | T23: =SUM(T18:U22) -> 10 | V23: =SUM(V18:W22) -> 0 | X23: =SUM(X18:Z22) -> 227
A24: SHIFT | D24: 1 TIME
D25: 1 TIME
A26: GRAND TOTAL | H26: =SUM(H17+H23+H24+H25) -> 130 | J26: =SUM(J17+J23+J24+J25) -> 2 | L26: =SUM(L17+L23+L24+L25) -> 324 | N26: =SUM(N17+N23+N24+N25) -> 0 | P26: =SUM(P17+P23+P24+P25) -> 36 | R26: =SUM(R17+R23+R24+R25) -> 1 | T26: =SUM(T17+T23+T24+T25) -> 10 | V26: =SUM(V17+V23+V24+V25) -> 0 | X26: =SUM(X17+X23+X24+X25) -> 503
A28: # WORKING PERIOD
A30: CRANE NO. | E30: FROM | K30: TO | Q30: HOURS | W30: REMARKS
A31: #1 (G/C)
Q43: =IF(AND(NOT(ISBLANK(K43)),NOT(ISBLANK(E43))), IF(K43>E43,K43-E43,24-E43+K43), "")
Q44: =IF(AND(NOT(ISBLANK(K44)),NOT(ISBLANK(E44))), IF(K44>E44,K44-E44,24-E44+K44), "")
Q45: =IF(AND(NOT(ISBLANK(K45)),NOT(ISBLANK(E45))), IF(K45>E45,K45-E45,24-E45+K45), "")
Q46: =IF(AND(NOT(ISBLANK(K46)),NOT(ISBLANK(E46))), IF(K46>E46,K46-E46,24-E46+K46), "")
Q47: =IF(AND(NOT(ISBLANK(K47)),NOT(ISBLANK(E47))), IF(K47>E47,K47-E47,24-E47+K47), "")
Q48: =IF(AND(NOT(ISBLANK(K48)),NOT(ISBLANK(E48))), IF(K48>E48,K48-E48,24-E48+K48), "")
Q49: =SUM(Q31:V48) -> 0
A50: CRANE NO. | E50: FROM | K50: TO | Q50: HOURS | W50: REMARKS
A51: #4 (G/C) | E51: 0.54166667 | Q51: =IF(AND(NOT(ISBLANK(K51)),NOT(ISBLANK(E51))), IF(K51>E51,K51-E51,24-E51+K51), "") | W51: COMMENCED DISCH.
A52: 24th | E52: =E51 -> 0.54166667 | K52: 0.72916667 | Q52: =IF(AND(NOT(ISBLANK(K52)),NOT(ISBLANK(E52))), IF(K52>E52,K52-E52,24-E52+K52), "") -> 0.1875 | W52: DISCH. OF CONT'R
E53: 0.72916667 | K53: 0.79166667 | Q53: =IF(AND(NOT(ISBLANK(K53)),NOT(ISBLANK(E53))), IF(K53>E53,K53-E53,24-E53+K53), "") -> 0.0625 | W53: MEAL TIME
E54: 0.79166667 | K54: 0.89930556 | Q54: =IF(AND(NOT(ISBLANK(K54)),NOT(ISBLANK(E54))), IF(K54>E54,K54-E54,24-E54+K54), "") -> 0.10763889 | W54: DISCH. OF CONT'R
K55: 0.89930556 | Q55: =IF(AND(NOT(ISBLANK(K55)),NOT(ISBLANK(E55))), IF(K55>E55,K55-E55,24-E55+K55), "") | W55: COMPLETED DISCH.
E56: 0.90277778 | Q56: =IF(AND(NOT(ISBLANK(K56)),NOT(ISBLANK(E56))), IF(K56>E56,K56-E56,24-E56+K56), "") | W56: COMMENCED LOAD.
E57: 0.90277778 | K57: 0.97916667 | Q57: =IF(AND(NOT(ISBLANK(K57)),NOT(ISBLANK(E57))), IF(K57>E57,K57-E57,24-E57+K57), "") -> 0.076388889 | W57: LOAD. OF CONT'R
...
